Workbook

Sheet Collection_Guide
A1: Purpose | B1: Master file for collecting 14 individual card-sorting responses and computing expert consensus.
A2: 1 | B2: Copy Evaluation!C6:C29 from each individual response workbook.
A3: 2 | B3: Paste values into one teacher/respondent column in the master Evaluation sheet.
A4: 3 | B4: Leave blanks as blanks. Valid N in pair data will exclude missing pairwise responses.
A5: 4 | B5: Do not sort rows or edit department names / row numbers.
A6: 5 | B6: Later merge Course similarity, Cluster co-membership, and Score difference into pair-data columns I-K.
A7: QA | B7: If a respondent uses only one group or almost all singleton groups, report sensitivity analysis with and without that response.

Sheet 안내
A1: 학과 유사성 평가 — Card Sorting
A3: ■ 연구 목적
A4: 고등학생 진로·진학 지도를 위한 학과 군집화 연구의 일환으로, 진학 지도 현장의 경험이 반영된 학과 유사성 체계를 구축하기 위한 평가입니다. 결과는 울산고교 과목로드맵 DB 고도화에 직접 활용될 예정입니다.
A6: ■ 가장 중요한 3가지 규칙
A7: ★ | B7: 비슷한 성격의 학과에는 같은 번호를, 다르다고 판단되면 다른 번호를 입력하세요.
A8: ★ | B8: 학과 순서는 무작위입니다. 순서 자체에는 의미가 없으니 신경 쓰지 마세요.
A9: ★ | B9: 반드시 큰 묶음을 만들 필요는 없습니다. 본인의 직관을 믿고 자유롭게 분류하세요.
A11: ■ 상세 평가 방법
A12: 1 | B12: 제시된 24개 학과를 "비슷한 성격의 학과끼리" 자유롭게 묶어주세요.
A13: 2 | B13: 판단 기준: "이 학생에게 A학과를 추천한다면 B학과도 함께 추천할 만한가?"
A14: 3 | B14: [평가] 시트에서 본인 이름이 적힌 열에 그룹 번호를 입력해주세요.
A15: 4 | B15: 같은 그룹이면 같은 숫자. 숫자는 자유롭게 사용하세요 (예: 1~5, 또는 1~10 등).
A16: 5 | B16: 예: 기계공학과와 조선해양공학과를 같은 그룹으로 묶는다면 둘 다 "1"을 입력.
A17: 6 | B17: 판단이 애매했던 학과는 오른쪽 "비고" 칸에 간단히 메모해주시면 큰 도움이 됩니다.
A18: 7 | B18: 독립적 판단이 중요하므로 다른 선생님과 상의하지 말아주세요. (평가 후 토론은 환영합니다.)
A20: ■ 소요 시간
A21: 약 30~40분 (충분히 시간을 가지고 판단해주세요)
A23: ■ 윤리적 고려
A24: 본 평가 데이터는 익명 처리되어 학술 연구 목적으로만 사용됩니다. 개인 식별 정보는 수집되지 않으며, 언제든지 참여를 철회하실 수 있습니다.
A26: 소중한 시간을 내주셔서 진심으로 감사드립니다.
A28: ■ 추가 유의사항: 그룹 번호는 각 평가자 내부에서만 의미가 있습니다. 여러 평가자가 한 파일을 공유하면 독립 판단이 훼손될 수 있으므로, 가능하면 평가자별 별도 사본으로 수집하세요.

Sheet 평가
A1: 학과 유사성 평가 — 본인 이름 열에 그룹 번호를, 헷갈린 학과는 비고 칸에 메모
A2: ★ 비슷한 학과에는 같은 번호 | ★ 다른 학과에는 다른 번호 | ★ 학과 순서는 무작위 (순서에 의미 없음)
A3: 예시) 기계공학과와 조선해양공학과를 같은 그룹으로 묶고 싶다면 둘 다 "1" 입력. 의예과를 다른 그룹으로 묶고 싶다면 "2" 입력. 그룹 수는 제한 없으니 3개든 10개든 자유롭게.
A5: 번호 | B5: 학과명 | C5: 담임1 | D5: 담임2 | E5: 담임3 | F5: 담임4 | G5: 담임5 | H5: 담임6 | I5: 담임7 | J5: 담임8 | K5: 담임9 | L5: 담임10 | M5: 담임11 | N5: 담임12 | O5: 담임13 | P5: 담임14 | Q5: 비고 (애매했던 학과만 메모) | R5: 응답 수 (자동)
A6: 1 | B6: 건축학과 | R6: =COUNTA(C6:P6)
A7: 2 | B7: 국어국문학과 | R7: =COUNTA(C7:P7)
A8: 3 | B8: 심리학과 | R8: =COUNTA(C8:P8)
A9: 4 | B9: 기계공학과 | R9: =COUNTA(C9:P9)
A10: 5 | B10: 화학과 | R10: =COUNTA(C10:P10)
A11: 6 | B11: 산업공학과 | R11: =COUNTA(C11:P11)
A12: 7 | B12: 신소재공학과 | R12: =COUNTA(C12:P12)
A13: 8 | B13: 조선해양공학과 | R13: =COUNTA(C13:P13)
A14: 9 | B14: 의예과 | R14: =COUNTA(C14:P14)
A15: 10 | B15: 수학과 | R15: =COUNTA(C15:P15)
A16: 11 | B16: 경영학과 | R16: =COUNTA(C16:P16)
A17: 12 | B17: 약학과 | R17: =COUNTA(C17:P17)
... A29: 24 | B29: 컴퓨터공학과 | R29: =COUNTA(C29:P29)
B31: 사용한 그룹 수 (자동)
B32: 완료율 (자동) | C32: =COUNTA(C6:C29)/24 | D32: =COUNTA(D6:D29)/24 | E32: =COUNTA(E6:E29)/24 | F32: =COUNTA(F6:F29)/24 | G32: =COUNTA(G6:G29)/24 | H32: =COUNTA(H6:H29)/24 | I32: =COUNTA(I6:I29)/24 | J32: =COUNTA(J6:J29)/24 | ... P32: =COUNTA(P6:P29)/24

Sheet 집계분석
A1: 집계 분석 — 학과 쌍별 공분류 빈도 (담임들이 같은 그룹에 넣은 비율)
A2: 이 시트는 평가가 완료되면 자동으로 계산됩니다. 각 셀은 "두 학과를 같은 그룹으로 분류한 담임 수 / 전체 응답 담임 수"를 나타냅니다. 1.0에 가까울수록 강한 합의, 0에 가까울수록 상이한 판단.
A4: 학과 | B4: 건축학과 | C4: 국어국문학과 | D4: 심리학과 | E4: 기계공학과 | F4: 화학과 | G4: 산업공학과 | H4: 신소재공학과 | I4: 조선해양공학과 | J4: 의예과 | K4: 수학과 | L4: 경영학과 | M4: 약학과 | N4: 사회학과 | O4: 경제학과 | P4: 생명과학과 | Q4: 미디어커뮤니케이션학과 | R4: 화학공학과 | S4: 디자인학과 | T4: 식품영양학과 | U4: 간호학과 | V4: 전기전자공학과 | W4: 사학과 | X4: 응용통계학과 | Y4: 컴퓨터공학과
A5: 건축학과 | B5: ="-" | C5: =IFERROR(SUMPRODUCT((평가!C6:P6<>"")*(평가!C7:P7<>"")*(평가!C6:P6=평가!C7:P7))/SUMPRODUCT((평가!C6:P6<>"")*(평가!C7:P7<>"")),"") | D5: =IFERROR(SUMPRODUCT((평가!C6:P6<>"")*(평가!C8:P8<>"")*(평가!C6:P6=평가!C8:P8))/SUMPRODUCT((평가!C6:P6<>"")*(평가!C8:P8<>"")),"") | E5: =IFERROR(SUMPRODUCT((평가!C6:P6<>"")*(평가!C9:P9<>"")*(평가!C6:P6=평가!C9:P9))/SUMPRODUCT((평가!C6:P6<>"")*(평가!C9:P9<>"")),"") | F5: =IFERROR(SUMPRODUCT((평가!C6:P6<>"")*(평가!C10:P10<>"")*(평가!C6:P6=평가!C10:P10))/SUMPRODUCT((평가!C6:P6<>"")*(평가!C10:P10<>"")),"") | G5: =IFERROR(SUMPRODUCT((평가!C6:P6<>"")*(평가!C11:P11<>"")*(평가!C6:P6=평가!C11:P11))/SUMPRODUCT((평가!C6:P6<>"")*(평가!C11:P11<>"")),"") | H5: =IFERROR(SUMPRODUCT((평가!C6:P6<>"")*(평가!C12:P12<>"")*(평가!C6:P6=평가!C12:P12))/SUMPRODUCT((평가!C6:P6<>"")*(평가!C12:P12<>"")),"") | I5: =IFERROR(SUMPRODUCT((평가!C6:P6<>"")*(평가!C13:P13<>"")*(평가!C6:P6=평가!C13:P13))/SUMPRODUCT((평가!C6:P6<>"")*(평가!C13:P13<>"")),"") | J5: =IFERROR(SUMPRODUCT((평가!C6:P6<>"")*(평가!C14:P14<>"")*(평가!C6:P6=평가!C14:P14))/SUMPRODUCT((평가!C6:P6<>"")*(평가!C14:P14<>"")),"") | K5: =IFERROR(SUMPRODUCT((평가!C6:P6<>"")*(평가!C15:P15<>"")*(평가!C6:P6=평가!C15:P15))/SUMPRODUCT((평가!C6:P6<>"")*(평가!C15:P15<>"")),"") | L5: =IFERROR(SUMPRODUCT((평가!C6:P6<>"")*(평가!C16:P16<>"")*(평가!C6:P6=평가!C16:P16))/SUMPRODUCT((평가!C6:P6<>"")*(평가!C16:P16<>"")),"") | M5: =IFERROR(SUMPRODUCT((평가!C6:P6<>"")*(평가!C17:P17<>"")*(평가!C6:P6=평가!C17:P17))/SUMPRODUCT((평가!C6:P6<>"")*(평가!C17:P17<>"")),"") | N5: =IFERROR(SUMPRODUCT((평가!C6:P6<>"")*(평가!C18:P18<>"")*(평가!C6:P6=평가!C18:P18))/SUMPRODUCT((평가!C6:P6<>"")*(평가!C18:P18<>"")),"") | O5: =IFERROR(SUMPRODUCT((평가!C6:P6<>"")*(평가!C19:P19<>"")*(평가!C6:P6=평가!C19:P19))/SUMPRODUCT((평가!C6:P6<>"")*(평가!C19:P19<>"")),"") | P5: =IFERROR(SUMPRODUCT((평가!C6:P6<>"")*(평가!C20:P20<>"")*(평가!C6:P6=평가!C20:P20))/SUMPRODUCT((평가!C6:P6<>"")*(평가!C20:P20<>"")),"") | Q5: =IFERROR(SUMPRODUCT((평가!C6:P6<>"")*(평가!C21:P21<>"")*(평가!C6:P6=평가!C21:P21))/SUMPRODUCT((평가!C6:P6<>"")*(평가!C21:P21<>"")),"") | R5: =IFERROR(SUMPRODUCT((평가!C6:P6<>"")*(평가!C22:P22<>"")*(평가!C6:P6=평가!C22:P22))/SUMPRODUCT((평가!C6:P6<>"")*(평가!C22:P22<>"")),"") | S5: =IFERROR(SUMPRODUCT((평가!C6:P6<>"")*(평가!C23:P23<>"")*(평가!C6:P6=평가!C23:P23))/SUMPRODUCT((평가!C6:P6<>"")*(평가!C23:P23<>"")),"") | T5: =IFERROR(SUMPRODUCT((평가!C6:P6<>"")*(평가!C24:P24<>"")*(평가!C6:P6=평가!C24:P24))/SUMPRODUCT((평가!C6:P6<>"")*(평가!C24:P24<>"")),"") | U5: =IFERROR(SUMPRODUCT((평가!C6:P6<>"")*(평가!C25:P25<>"")*(평가!C6:P6=평가!C25:P25))/SUMPRODUCT((평가!C6:P6<>"")*(평가!C25:P25<>"")),"") | V5: =IFERROR(SUMPRODUCT((평가!C6:P6<>"")*(평가!C26:P26<>"")*(평가!C6:P6=평가!C26:P26))/SUMPRODUCT((평가!C6:P6<>"")*(평가!C26:P26<>"")),"") | W5: =IFERROR(SUMPRODUCT((평가!C6:P6<>"")*(평가!C27:P27<>"")*(평가!C6:P6=평가!C27:P27))/SUMPRODUCT((평가!C6:P6<>"")*(평가!C27:P27<>"")),"") | X5: =IFERROR(SUMPRODUCT((평가!C6:P6<>"")*(평가!C28:P28<>"")*(평가!C6:P6=평가!C28:P28))/SUMPRODUCT((평가!C6:P6<>"")*(평가!C28:P28<>"")),"") | Y5: =IFERROR(SUMPRODUCT((평가!C6:P6<>"")*(평가!C29:P29<>"")*(평가!C6:P6=평가!C29:P29))/SUMPRODUCT((평가!C6:P6<>"")*(평가!C29:P29<>"")),"")
A6: 국어국문학과 | B6: =IFERROR(SUMPRODUCT((평가!C7:P7<>"")*(평가!C6:P6<>"")*(평가!C7:P7=평가!C6:P6))/SUMPRODUCT((평가!C7:P7<>"")*(평가!C6:P6<>"")),"") | C6: ="-" | D6: =IFERROR(SUMPRODUCT((평가!C7:P7<>"")*(평가!C8:P8<>"")*(평가!C7:P7=평가!C8:P8))/SUMPRODUCT((평가!C7:P7<>"")*(평가!C8:P8<>"")),"") | E6: =IFERROR(SUMPRODUCT((평가!C7:P7<>"")*(평가!C9:P9<>"")*(평가!C7:P7=평가!C9:P9))/SUMPRODUCT((평가!C7:P7<>"")*(평가!C9:P9<>"")),"") | F6: =IFERROR(SUMPRODUCT((평가!C7:P7<>"")*(평가!C10:P10<>"")*(평가!C7:P7=평가!C10:P10))/SUMPRODUCT((평가!C7:P7<>"")*(평가!C10:P10<>"")),"") | G6: =IFERROR(SUMPRODUCT((평가!C7:P7<>"")*(평가!C11:P11<>"")*(평가!C7:P7=평가!C11:P11))/SUMPRODUCT((평가!C7:P7<>"")*(평가!C11:P11<>"")),"") | H6: =IFERROR(SUMPRODUCT((평가!C7:P7<>"")*(평가!C12:P12<>"")*(평가!C7:P7=평가!C12:P12))/SUMPRODUCT((평가!C7:P7<>"")*(평가!C12:P12<>"")),"") | I6: =IFERROR(SUMPRODUCT((평가!C7:P7<>"")*(평가!C13:P13<>"")*(평가!C7:P7=평가!C13:P13))/SUMPRODUCT((평가!C7:P7<>"")*(평가!C13:P13<>"")),"") | J6: =IFERROR(SUMPRODUCT((평가!C7:P7<>"")*(평가!C14:P14<>"")*(평가!C7:P7=평가!C14:P14))/SUMPRODUCT((평가!C7:P7<>"")*(평가!C14:P14<>"")),"") | K6: =IFERROR(SUMPRODUCT((평가!C7:P7<>"")*(평가!C15:P15<>"")*(평가!C7:P7=평가!C15:P15))/SUMPRODUCT((평가!C7:P7<>"")*(평가!C15:P15<>"")),"") | L6: =IFERROR(SUMPRODUCT((평가!C7:P7<>"")*(평가!C16:P16<>"")*(평가!C7:P7=평가!C16:P16))/SUMPRODUCT((평가!C7:P7<>"")*(평가!C16:P16<>"")),"") | M6: =IFERROR(SUMPRODUCT((평가!C7:P7<>"")*(평가!C17:P17<>"")*(평가!C7:P7=평가!C17:P17))/SUMPRODUCT((평가!C7:P7<>"")*(평가!C17:P17<>"")),"") | N6: =IFERROR(SUMPRODUCT((평가!C7:P7<>"")*(평가!C18:P18<>"")*(평가!C7:P7=평가!C18:P18))/SUMPRODUCT((평가!C7:P7<>"")*(평가!C18:P18<>"")),"") | O6: =IFERROR(SUMPRODUCT((평가!C7:P7<>"")*(평가!C19:P19<>"")*(평가!C7:P7=평가!C19:P19))/SUMPRODUCT((평가!C7:P7<>"")*(평가!C19:P19<>"")),"") | P6: =IFERROR(SUMPRODUCT((평가!C7:P7<>"")*(평가!C20:P20<>"")*(평가!C7:P7=평가!C20:P20))/SUMPRODUCT((평가!C7:P7<>"")*(평가!C20:P20<>"")),"") | Q6: =IFERROR(SUMPRODUCT((평가!C7:P7<>"")*(평가!C21:P21<>"")*(평가!C7:P7=평가!C21:P21))/SUMPRODUCT((평가!C7:P7<>"")*(평가!C21:P21<>"")),"") | R6: =IFERROR(SUMPRODUCT((평가!C7:P7<>"")*(평가!C22:P22<>"")*(평가!C7:P7=평가!C22:P22))/SUMPRODUCT((평가!C7:P7<>"")*(평가!C22:P22<>"")),"") | S6: =IFERROR(SUMPRODUCT((평가!C7:P7<>"")*(평가!C23:P23<>"")*(평가!C7:P7=평가!C23:P23))/SUMPRODUCT((평가!C7:P7<>"")*(평가!C23:P23<>"")),"") | T6: =IFERROR(SUMPRODUCT((평가!C7:P7<>"")*(평가!C24:P24<>"")*(평가!C7:P7=평가!C24:P24))/SUMPRODUCT((평가!C7:P7<>"")*(평가!C24:P24<>"")),"") | U6: =IFERROR(SUMPRODUCT((평가!C7:P7<>"")*(평가!C25:P25<>"")*(평가!C7:P7=평가!C25:P25))/SUMPRODUCT((평가!C7:P7<>"")*(평가!C25:P25<>"")),"") | V6: =IFERROR(SUMPRODUCT((평가!C7:P7<>"")*(평가!C26:P26<>"")*(평가!C7:P7=평가!C26:P26))/SUMPRODUCT((평가!C7:P7<>"")*(평가!C26:P26<>"")),"") | W6: =IFERROR(SUMPRODUCT((평가!C7:P7<>"")*(평가!C27:P27<>"")*(평가!C7:P7=평가!C27:P27))/SUMPRODUCT((평가!C7:P7<>"")*(평가!C27:P27<>"")),"") | X6: =IFERROR(SUMPRODUCT((평가!C7:P7<>"")*(평가!C28:P28<>"")*(평가!C7:P7=평가!C28:P28))/SUMPRODUCT((평가!C7:P7<>"")*(평가!C28:P28<>"")),"") | Y6: =IFERROR(SUMPRODUCT((평가!C7:P7<>"")*(평가!C29:P29<>"")*(평가!C7:P7=평가!C29:P29))/SUMPRODUCT((평가!C7:P7<>"")*(평가!C29:P29<>"")),"")
A7: 심리학과 | B7: =IFERROR(SUMPRODUCT((평가!C8:P8<>"")*(평가!C6:P6<>"")*(평가!C8:P8=평가!C6:P6))/SUMPRODUCT((평가!C8:P8<>"")*(평가!C6:P6<>"")),"") | C7: =IFERROR(SUMPRODUCT((평가!C8:P8<>"")*(평가!C7:P7<>"")*(평가!C8:P8=평가!C7:P7))/SUMPRODUCT((평가!C8:P8<>"")*(평가!C7:P7<>"")),"") | D7: ="-" | E7: =IFERROR(SUMPRODUCT((평가!C8:P8<>"")*(평가!C9:P9<>"")*(평가!C8:P8=평가!C9:P9))/SUMPRODUCT((평가!C8:P8<>"")*(평가!C9:P9<>"")),"") | F7: =IFERROR(SUMPRODUCT((평가!C8:P8<>"")*(평가!C10:P10<>"")*(평가!C8:P8=평가!C10:P10))/SUMPRODUCT((평가!C8:P8<>"")*(평가!C10:P10<>"")),"") | G7: =IFERROR(SUMPRODUCT((평가!C8:P8<>"")*(평가!C11:P11<>"")*(평가!C8:P8=평가!C11:P11))/SUMPRODUCT((평가!C8:P8<>"")*(평가!C11:P11<>"")),"") | H7: =IFERROR(SUMPRODUCT((평가!C8:P8<>"")*(평가!C12:P12<>"")*(평가!C8:P8=평가!C12:P12))/SUMPRODUCT((평가!C8:P8<>"")*(평가!C12:P12<>"")),"") | I7: =IFERROR(SUMPRODUCT((평가!C8:P8<>"")*(평가!C13:P13<>"")*(평가!C8:P8=평가!C13:P13))/SUMPRODUCT((평가!C8:P8<>"")*(평가!C13:P13<>"")),"") | J7: =IFERROR(SUMPRODUCT((평가!C8:P8<>"")*(평가!C14:P14<>"")*(평가!C8:P8=평가!C14:P14))/SUMPRODUCT((평가!C8:P8<>"")*(평가!C14:P14<>"")),"") | K7: =IFERROR(SUMPRODUCT((평가!C8:P8<>"")*(평가!C15:P15<>"")*(평가!C8:P8=평가!C15:P15))/SUMPRODUCT((평가!C8:P8<>"")*(평가!C15:P15<>"")),"") | L7: =IFERROR(SUMPRODUCT((평가!C8:P8<>"")*(평가!C16:P16<>"")*(평가!C8:P8=평가!C16:P16))/SUMPRODUCT((평가!C8:P8<>"")*(평가!C16:P16<>"")),"") | M7: =IFERROR(SUMPRODUCT((평가!C8:P8<>"")*(평가!C17:P17<>"")*(평가!C8:P8=평가!C17:P17))/SUMPRODUCT((평가!C8:P8<>"")*(평가!C17:P17<>"")),"") | N7: =IFERROR(SUMPRODUCT((평가!C8:P8<>"")*(평가!C18:P18<>"")*(평가!C8:P8=평가!C18:P18))/SUMPRODUCT((평가!C8:P8<>"")*(평가!C18:P18<>"")),"") | O7: =IFERROR(SUMPRODUCT((평가!C8:P8<>"")*(평가!C19:P19<>"")*(평가!C8:P8=평가!C19:P19))/SUMPRODUCT((평가!C8:P8<>"")*(평가!C19:P19<>"")),"") | P7: =IFERROR(SUMPRODUCT((평가!C8:P8<>"")*(평가!C20:P20<>"")*(평가!C8:P8=평가!C20:P20))/SUMPRODUCT((평가!C8:P8<>"")*(평가!C20:P20<>"")),"") | Q7: =IFERROR(SUMPRODUCT((평가!C8:P8<>"")*(평가!C21:P21<>"")*(평가!C8:P8=평가!C21:P21))/SUMPRODUCT((평가!C8:P8<>"")*(평가!C21:P21<>"")),"") | R7: =IFERROR(SUMPRODUCT((평가!C8:P8<>"")*(평가!C22:P22<>"")*(평가!C8:P8=평가!C22:P22))/SUMPRODUCT((평가!C8:P8<>"")*(평가!C22:P22<>"")),"") | S7: =IFERROR(SUMPRODUCT((평가!C8:P8<>"")*(평가!C23:P23<>"")*(평가!C8:P8=평가!C23:P23))/SUMPRODUCT((평가!C8:P8<>"")*(평가!C23:P23<>"")),"") | T7: =IFERROR(SUMPRODUCT((평가!C8:P8<>"")*(평가!C24:P24<>"")*(평가!C8:P8=평가!C24:P24))/SUMPRODUCT((평가!C8:P8<>"")*(평가!C24:P24<>"")),"") | U7: =IFERROR(SUMPRODUCT((평가!C8:P8<>"")*(평가!C25:P25<>"")*(평가!C8:P8=평가!C25:P25))/SUMPRODUCT((평가!C8:P8<>"")*(평가!C25:P25<>"")),"") | V7: =IFERROR(SUMPRODUCT((평가!C8:P8<>"")*(평가!C26:P26<>"")*(평가!C8:P8=평가!C26:P26))/SUMPRODUCT((평가!C8:P8<>"")*(평가!C26:P26<>"")),"") | W7: =IFERROR(SUMPRODUCT((평가!C8:P8<>"")*(평가!C27:P27<>"")*(평가!C8:P8=평가!C27:P27))/SUMPRODUCT((평가!C8:P8<>"")*(평가!C27:P27<>"")),"") | X7: =IFERROR(SUMPRODUCT((평가!C8:P8<>"")*(평가!C28:P28<>"")*(평가!C8:P8=평가!C28:P28))/SUMPRODUCT((평가!C8:P8<>"")*(평가!C28:P28<>"")),"") | Y7: =IFERROR(SUMPRODUCT((평가!C8:P8<>"")*(평가!C29:P29<>"")*(평가!C8:P8=평가!C29:P29))/SUMPRODUCT((평가!C8:P8<>"")*(평가!C29:P29<>"")),"")
A8: 기계공학과 | B8: =IFERROR(SUMPRODUCT((평가!C9:P9<>"")*(평가!C6:P6<>"")*(평가!C9:P9=평가!C6:P6))/SUMPRODUCT((평가!C9:P9<>"")*(평가!C6:P6<>"")),"") | C8: =IFERROR(SUMPRODUCT((평가!C9:P9<>"")*(평가!C7:P7<>"")*(평가!C9:P9=평가!C7:P7))/SUMPRODUCT((평가!C9:P9<>"")*(평가!C7:P7<>"")),"") | D8: =IFERROR(SUMPRODUCT((평가!C9:P9<>"")*(평가!C8:P8<>"")*(평가!C9:P9=평가!C8:P8))/SUMPRODUCT((평가!C9:P9<>"")*(평가!C8:P8<>"")),"") | E8: ="-" | F8: =IFERROR(SUMPRODUCT((평가!C9:P9<>"")*(평가!C10:P10<>"")*(평가!C9:P9=평가!C10:P10))/SUMPRODUCT((평가!C9:P9<>"")*(평가!C10:P10<>"")),"") | G8: =IFERROR(SUMPRODUCT((평가!C9:P9<>"")*(평가!C11:P11<>"")*(평가!C9:P9=평가!C11:P11))/SUMPRODUCT((평가!C9:P9<>"")*(평가!C11:P11<>"")),"") | H8: =IFERROR(SUMPRODUCT((평가!C9:P9<>"")*(평가!C12:P12<>"")*(평가!C9:P9=평가!C12:P12))/SUMPRODUCT((평가!C9:P9<>"")*(평가!C12:P12<>"")),"") | I8: =IFERROR(SUMPRODUCT((평가!C9:P9<>"")*(평가!C13:P13<>"")*(평가!C9:P9=평가!C13:P13))/SUMPRODUCT((평가!C9:P9<>"")*(평가!C13:P13<>"")),"") | J8: =IFERROR(SUMPRODUCT((평가!C9:P9<>"")*(평가!C14:P14<>"")*(평가!C9:P9=평가!C14:P14))/SUMPRODUCT((평가!C9:P9<>"")*(평가!C14:P14<>"")),"") | K8: =IFERROR(SUMPRODUCT((평가!C9:P9<>"")*(평가!C15:P15<>"")*(평가!C9:P9=평가!C15:P15))/SUMPRODUCT((평가!C9:P9<>"")*(평가!C15:P15<>"")),"") | L8: =IFERROR(SUMPRODUCT((평가!C9:P9<>"")*(평가!C16:P16<>"")*(평가!C9:P9=평가!C16:P16))/SUMPRODUCT((평가!C9:P9<>"")*(평가!C16:P16<>"")),"") | M8: =IFERROR(SUMPRODUCT((평가!C9:P9<>"")*(평가!C17:P17<>"")*(평가!C9:P9=평가!C17:P17))/SUMPRODUCT((평가!C9:P9<>"")*(평가!C17:P17<>"")),"") | N8: =IFERROR(SUMPRODUCT((평가!C9:P9<>"")*(평가!C18:P18<>"")*(평가!C9:P9=평가!C18:P18))/SUMPRODUCT((평가!C9:P9<>"")*(평가!C18:P18<>"")),"") | O8: =IFERROR(SUMPRODUCT((평가!C9:P9<>"")*(평가!C19:P19<>"")*(평가!C9:P9=평가!C19:P19))/SUMPRODUCT((평가!C9:P9<>"")*(평가!C19:P19<>"")),"") | P8: =IFERROR(SUMPRODUCT((평가!C9:P9<>"")*(평가!C20:P20<>"")*(평가!C9:P9=평가!C20:P20))/SUMPRODUCT((평가!C9:P9<>"")*(평가!C20:P20<>"")),"") | Q8: =IFERROR(SUMPRODUCT((평가!C9:P9<>"")*(평가!C21:P21<>"")*(평가!C9:P9=평가!C21:P21))/SUMPRODUCT((평가!C9:P9<>"")*(평가!C21:P21<>"")),"") | R8: =IFERROR(SUMPRODUCT((평가!C9:P9<>"")*(평가!C22:P22<>"")*(평가!C9:P9=평가!C22:P22))/SUMPRODUCT((평가!C9:P9<>"")*(평가!C22:P22<>"")),"") | S8: =IFERROR(SUMPRODUCT((평가!C9:P9<>"")*(평가!C23:P23<>"")*(평가!C9:P9=평가!C23:P23))/SUMPRODUCT((평가!C9:P9<>"")*(평가!C23:P23<>"")),"") | T8: =IFERROR(SUMPRODUCT((평가!C9:P9<>"")*(평가!C24:P24<>"")*(평가!C9:P9=평가!C24:P24))/SUMPRODUCT((평가!C9:P9<>"")*(평가!C24:P24<>"")),"") | U8: =IFERROR(SUMPRODUCT((평가!C9:P9<>"")*(평가!C25:P25<>"")*(평가!C9:P9=평가!C25:P25))/SUMPRODUCT((평가!C9:P9<>"")*(평가!C25:P25<>"")),"") | V8: =IFERROR(SUMPRODUCT((평가!C9:P9<>"")*(평가!C26:P26<>"")*(평가!C9:P9=평가!C26:P26))/SUMPRODUCT((평가!C9:P9<>"")*(평가!C26:P26<>"")),"") | W8: =IFERROR(SUMPRODUCT((평가!C9:P9<>"")*(평가!C27:P27<>"")*(평가!C9:P9=평가!C27:P27))/SUMPRODUCT((평가!C9:P9<>"")*(평가!C27:P27<>"")),"") | X8: =IFERROR(SUMPRODUCT((평가!C9:P9<>"")*(평가!C28:P28<>"")*(평가!C9:P9=평가!C28:P28))/SUMPRODUCT((평가!C9:P9<>"")*(평가!C28:P28<>"")),"") | Y8: =IFERROR(SUMPRODUCT((평가!C9:P9<>"")*(평가!C29:P29<>"")*(평가!C9:P9=평가!C29:P29))/SUMPRODUCT((평가!C9:P9<>"")*(평가!C29:P29<>"")),"")
A9: 화학과 | B9: =IFERROR(SUMPRODUCT((평가!C10:P10<>"")*(평가!C6:P6<>"")*(평가!C10:P10=평가!C6:P6))/SUMPRODUCT((평가!C10:P10<>"")*(평가!C6:P6<>"")),"") | C9: =IFERROR(SUMPRODUCT((평가!C10:P10<>"")*(평가!C7:P7<>"")*(평가!C10:P10=평가!C7:P7))/SUMPRODUCT((평가!C10:P10<>"")*(평가!C7:P7<>"")),"") | D9: =IFERROR(SUMPRODUCT((평가!C10:P10<>"")*(평가!C8:P8<>"")*(평가!C10:P10=평가!C8:P8))/SUMPRODUCT((평가!C10:P10<>"")*(평가!C8:P8<>"")),"") | E9: =IFERROR(SUMPRODUCT((평가!C10:P10<>"")*(평가!C9:P9<>"")*(평가!C10:P10=평가!C9:P9))/SUMPRODUCT((평가!C10:P10<>"")*(평가!C9:P9<>"")),"") | F9: ="-" | G9: =IFERROR(SUMPRODUCT((평가!C10:P10<>"")*(평가!C11:P11<>"")*(평가!C10:P10=평가!C11:P11))/SUMPRODUCT((평가!C10:P10<>"")*(평가!C11:P11<>"")),"") | H9: =IFERROR(SUMPRODUCT((평가!C10:P10<>"")*(평가!C12:P12<>"")*(평가!C10:P10=평가!C12:P12))/SUMPRODUCT((평가!C10:P10<>"")*(평가!C12:P12<>"")),"") | I9: =IFERROR(SUMPRODUCT((평가!C10:P10<>"")*(평가!C13:P13<>"")*(평가!C10:P10=평가!C13:P13))/SUMPRODUCT((평가!C10:P10<>"")*(평가!C13:P13<>"")),"") | J9: =IFERROR(SUMPRODUCT((평가!C10:P10<>"")*(평가!C14:P14<>"")*(평가!C10:P10=평가!C14:P14))/SUMPRODUCT((평가!C10:P10<>"")*(평가!C14:P14<>"")),"") | K9: =IFERROR(SUMPRODUCT((평가!C10:P10<>"")*(평가!C15:P15<>"")*(평가!C10:P10=평가!C15:P15))/SUMPRODUCT((평가!C10:P10<>"")*(평가!C15:P15<>"")),"") | L9: =IFERROR(SUMPRODUCT((평가!C10:P10<>"")*(평가!C16:P16<>"")*(평가!C10:P10=평가!C16:P16))/SUMPRODUCT((평가!C10:P10<>"")*(평가!C16:P16<>"")),"") | M9: =IFERROR(SUMPRODUCT((평가!C10:P10<>"")*(평가!C17:P17<>"")*(평가!C10:P10=평가!C17:P17))/SUMPRODUCT((평가!C10:P10<>"")*(평가!C17:P17<>"")),"") | N9: =IFERROR(SUMPRODUCT((평가!C10:P10<>"")*(평가!C18:P18<>"")*(평가!C10:P10=평가!C18:P18))/SUMPRODUCT((평가!C10:P10<>"")*(평가!C18:P18<>"")),"") | O9: =IFERROR(SUMPRODUCT((평가!C10:P10<>"")*(평가!C19:P19<>"")*(평가!C10:P10=평가!C19:P19))/SUMPRODUCT((평가!C10:P10<>"")*(평가!C19:P19<>"")),"") | P9: =IFERROR(SUMPRODUCT((평가!C10:P10<>"")*(평가!C20:P20<>"")*(평가!C10:P10=평가!C20:P20))/SUMPRODUCT((평가!C10:P10<>"")*(평가!C20:P20<>"")),"") | Q9: =IFERROR(SUMPRODUCT((평가!C10:P10<>"")*(평가!C21:P21<>"")*(평가!C10:P10=평가!C21:P21))/SUMPRODUCT((평가!C10:P10<>"")*(평가!C21:P21<>"")),"") | R9: =IFERROR(SUMPRODUCT((평가!C10:P10<>"")*(평가!C22:P22<>"")*(평가!C10:P10=평가!C22:P22))/SUMPRODUCT((평가!C10:P10<>"")*(평가!C22:P22<>"")),"") | S9: =IFERROR(SUMPRODUCT((평가!C10:P10<>"")*(평가!C23:P23<>"")*(평가!C10:P10=평가!C23:P23))/SUMPRODUCT((평가!C10:P10<>"")*(평가!C23:P23<>"")),"") | T9: =IFERROR(SUMPRODUCT((평가!C10:P10<>"")*(평가!C24:P24<>"")*(평가!C10:P10=평가!C24:P24))/SUMPRODUCT((평가!C10:P10<>"")*(평가!C24:P24<>"")),"") | U9: =IFERROR(SUMPRODUCT((평가!C10:P10<>"")*(평가!C25:P25<>"")*(평가!C10:P10=평가!C25:P25))/SUMPRODUCT((평가!C10:P10<>"")*(평가!C25:P25<>"")),"") | V9: =IFERROR(SUMPRODUCT((평가!C10:P10<>"")*(평가!C26:P26<>"")*(평가!C10:P10=평가!C26:P26))/SUMPRODUCT((평가!C10:P10<>"")*(평가!C26:P26<>"")),"") | W9: =IFERROR(SUMPRODUCT((평가!C10:P10<>"")*(평가!C27:P27<>"")*(평가!C10:P10=평가!C27:P27))/SUMPRODUCT((평가!C10:P10<>"")*(평가!C27:P27<>"")),"") | X9: =IFERROR(SUMPRODUCT((평가!C10:P10<>"")*(평가!C28:P28<>"")*(평가!C10:P10=평가!C28:P28))/SUMPRODUCT((평가!C10:P10<>"")*(평가!C28:P28<>"")),"") | Y9: =IFERROR(SUMPRODUCT((평가!C10:P10<>"")*(평가!C29:P29<>"")*(평가!C10:P10=평가!C29:P29))/SUMPRODUCT((평가!C10:P10<>"")*(평가!C29:P29<>"")),"")
A10: 산업공학과 | B10: =IFERROR(SUMPRODUCT((평가!C11:P11<>"")*(평가!C6:P6<>"")*(평가!C11:P11=평가!C6:P6))/SUMPRODUCT((평가!C11:P11<>"")*(평가!C6:P6<>"")),"") | C10: =IFERROR(SUMPRODUCT((평가!C11:P11<>"")*(평가!C7:P7<>"")*(평가!C11:P11=평가!C7:P7))/SUMPRODUCT((평가!C11:P11<>"")*(평가!C7:P7<>"")),"") | D10: =IFERROR(SUMPRODUCT((평가!C11:P11<>"")*(평가!C8:P8<>"")*(평가!C11:P11=평가!C8:P8))/SUMPRODUCT((평가!C11:P11<>"")*(평가!C8:P8<>"")),"") | E10: =IFERROR(SUMPRODUCT((평가!C11:P11<>"")*(평가!C9:P9<>"")*(평가!C11:P11=평가!C9:P9))/SUMPRODUCT((평가!C11:P11<>"")*(평가!C9:P9<>"")),"") | F10: =IFERROR(SUMPRODUCT((평가!C11:P11<>"")*(평가!C10:P10<>"")*(평가!C11:P11=평가!C10:P10))/SUMPRODUCT((평가!C11:P11<>"")*(평가!C10:P10<>"")),"") | G10: ="-" | H10: =IFERROR(SUMPRODUCT((평가!C11:P11<>"")*(평가!C12:P12<>"")*(평가!C11:P11=평가!C12:P12))/SUMPRODUCT((평가!C11:P11<>"")*(평가!C12:P12<>"")),"") | I10: =IFERROR(SUMPRODUCT((평가!C11:P11<>"")*(평가!C13:P13<>"")*(평가!C11:P11=평가!C13:P13))/SUMPRODUCT((평가!C11:P11<>"")*(평가!C13:P13<>"")),"") | J10: =IFERROR(SUMPRODUCT((평가!C11:P11<>"")*(평가!C14:P14<>"")*(평가!C11:P11=평가!C14:P14))/SUMPRODUCT((평가!C11:P11<>"")*(평가!C14:P14<>"")),"") | K10: =IFERROR(SUMPRODUCT((평가!C11:P11<>"")*(평가!C15:P15<>"")*(평가!C11:P11=평가!C15:P15))/SUMPRODUCT((평가!C11:P11<>"")*(평가!C15:P15<>"")),"") | L10: =IFERROR(SUMPRODUCT((평가!C11:P11<>"")*(평가!C16:P16<>"")*(평가!C11:P11=평가!C16:P16))/SUMPRODUCT((평가!C11:P11<>"")*(평가!C16:P16<>"")),"") | M10: =IFERROR(SUMPRODUCT((평가!C11:P11<>"")*(평가!C17:P17<>"")*(평가!C11:P11=평가!C17:P17))/SUMPRODUCT((평가!C11:P11<>"")*(평가!C17:P17<>"")),"") | N10: =IFERROR(SUMPRODUCT((평가!C11:P11<>"")*(평가!C18:P18<>"")*(평가!C11:P11=평가!C18:P18))/SUMPRODUCT((평가!C11:P11<>"")*(평가!C18:P18<>"")),"") | O10: =IFERROR(SUMPRODUCT((평가!C11:P11<>"")*(평가!C19:P19<>"")*(평가!C11:P11=평가!C19:P19))/SUMPRODUCT((평가!C11:P11<>"")*(평가!C19:P19<>"")),"") | P10: =IFERROR(SUMPRODUCT((평가!C11:P11<>"")*(평가!C20:P20<>"")*(평가!C11:P11=평가!C20:P20))/SUMPRODUCT((평가!C11:P11<>"")*(평가!C20:P20<>"")),"") | Q10: =IFERROR(SUMPRODUCT((평가!C11:P11<>"")*(평가!C21:P21<>"")*(평가!C11:P11=평가!C21:P21))/SUMPRODUCT((평가!C11:P11<>"")*(평가!C21:P21<>"")),"") | R10: =IFERROR(SUMPRODUCT((평가!C11:P11<>"")*(평가!C22:P22<>"")*(평가!C11:P11=평가!C22:P22))/SUMPRODUCT((평가!C11:P11<>"")*(평가!C22:P22<>"")),"") | S10: =IFERROR(SUMPRODUCT((평가!C11:P11<>"")*(평가!C23:P23<>"")*(평가!C11:P11=평가!C23:P23))/SUMPRODUCT((평가!C11:P11<>"")*(평가!C23:P23<>"")),"") | T10: =IFERROR(SUMPRODUCT((평가!C11:P11<>"")*(평가!C24:P24<>"")*(평가!C11:P11=평가!C24:P24))/SUMPRODUCT((평가!C11:P11<>"")*(평가!C24:P24<>"")),"") | U10: =IFERROR(SUMPRODUCT((평가!C11:P11<>"")*(평가!C25:P25<>"")*(평가!C11:P11=평가!C25:P25))/SUMPRODUCT((평가!C11:P11<>"")*(평가!C25:P25<>"")),"") | V10: =IFERROR(SUMPRODUCT((평가!C11:P11<>"")*(평가!C26:P26<>"")*(평가!C11:P11=평가!C26:P26))/SUMPRODUCT((평가!C11:P11<>"")*(평가!C26:P26<>"")),"") | W10: =IFERROR(SUMPRODUCT((평가!C11:P11<>"")*(평가!C27:P27<>"")*(평가!C11:P11=평가!C27:P27))/SUMPRODUCT((평가!C11:P11<>"")*(평가!C27:P27<>"")),"") | X10: =IFERROR(SUMPRODUCT((평가!C11:P11<>"")*(평가!C28:P28<>"")*(평가!C11:P11=평가!C28:P28))/SUMPRODUCT((평가!C11:P11<>"")*(평가!C28:P28<>"")),"") | Y10: =IFERROR(SUMPRODUCT((평가!C11:P11<>"")*(평가!C29:P29<>"")*(평가!C11:P11=평가!C29:P29))/SUMPRODUCT((평가!C11:P11<>"")*(평가!C29:P29<>"")),"")
A11: 신소재공학과 | B11: =IFERROR(SUMPRODUCT((평가!C12:P12<>"")*(평가!C6:P6<>"")*(평가!C12:P12=평가!C6:P6))/SUMPRODUCT((평가!C12:P12<>"")*(평가!C6:P6<>"")),"") | C11: =IFERROR(SUMPRODUCT((평가!C12:P12<>"")*(평가!C7:P7<>"")*(평가!C12:P12=평가!C7:P7))/SUMPRODUCT((평가!C12:P12<>"")*(평가!C7:P7<>"")),"") | D11: =IFERROR(SUMPRODUCT((평가!C12:P12<>"")*(평가!C8:P8<>"")*(평가!C12:P12=평가!C8:P8))/SUMPRODUCT((평가!C12:P12<>"")*(평가!C8:P8<>"")),"") | E11: =IFERROR(SUMPRODUCT((평가!C12:P12<>"")*(평가!C9:P9<>"")*(평가!C12:P12=평가!C9:P9))/SUMPRODUCT((평가!C12:P12<>"")*(평가!C9:P9<>"")),"") | F11: =IFERROR(SUMPRODUCT((평가!C12:P12<>"")*(평가!C10:P10<>"")*(평가!C12:P12=평가!C10:P10))/SUMPRODUCT((평가!C12:P12<>"")*(평가!C10:P10<>"")),"") | G11: =IFERROR(SUMPRODUCT((평가!C12:P12<>"")*(평가!C11:P11<>"")*(평가!C12:P12=평가!C11:P11))/SUMPRODUCT((평가!C12:P12<>"")*(평가!C11:P11<>"")),"") | H11: ="-" | I11: =IFERROR(SUMPRODUCT((평가!C12:P12<>"")*(평가!C13:P13<>"")*(평가!C12:P12=평가!C13:P13))/SUMPRODUCT((평가!C12:P12<>"")*(평가!C13:P13<>"")),"") | J11: =IFERROR(SUMPRODUCT((평가!C12:P12<>"")*(평가!C14:P14<>"")*(평가!C12:P12=평가!C14:P14))/SUMPRODUCT((평가!C12:P12<>"")*(평가!C14:P14<>"")),"") | K11: =IFERROR(SUMPRODUCT((평가!C12:P12<>"")*(평가!C15:P15<>"")*(평가!C12:P12=평가!C15:P15))/SUMPRODUCT((평가!C12:P12<>"")*(평가!C15:P15<>"")),"") | L11: =IFERROR(SUMPRODUCT((평가!C12:P12<>"")*(평가!C16:P16<>"")*(평가!C12:P12=평가!C16:P16))/SUMPRODUCT((평가!C12:P12<>"")*(평가!C16:P16<>"")),"") | M11: =IFERROR(SUMPRODUCT((평가!C12:P12<>"")*(평가!C17:P17<>"")*(평가!C12:P12=평가!C17:P17))/SUMPRODUCT((평가!C12:P12<>"")*(평가!C17:P17<>"")),"") | N11: =IFERROR(SUMPRODUCT((평가!C12:P12<>"")*(평가!C18:P18<>"")*(평가!C12:P12=평가!C18:P18))/SUMPRODUCT((평가!C12:P12<>"")*(평가!C18:P18<>"")),"") | O11: =IFERROR(SUMPRODUCT((평가!C12:P12<>"")*(평가!C19:P19<>"")*(평가!C12:P12=평가!C19:P19))/SUMPRODUCT((평가!C12:P12<>"")*(평가!C19:P19<>"")),"") | P11: =IFERROR(SUMPRODUCT((평가!C12:P12<>"")*(평가!C20:P20<>"")*(평가!C12:P12=평가!C20:P20))/SUMPRODUCT((평가!C12:P12<>"")*(평가!C20:P20<>"")),"") | Q11: =IFERROR(SUMPRODUCT((평가!C12:P12<>"")*(평가!C21:P21<>"")*(평가!C12:P12=평가!C21:P21))/SUMPRODUCT((평가!C12:P12<>"")*(평가!C21:P21<>"")),"") | R11: =IFERROR(SUMPRODUCT((평가!C12:P12<>"")*(평가!C22:P22<>"")*(평가!C12:P12=평가!C22:P22))/SUMPRODUCT((평가!C12:P12<>"")*(평가!C22:P22<>"")),"") | S11: =IFERROR(SUMPRODUCT((평가!C12:P12<>"")*(평가!C23:P23<>"")*(평가!C12:P12=평가!C23:P23))/SUMPRODUCT((평가!C12:P12<>"")*(평가!C23:P23<>"")),"") | T11: =IFERROR(SUMPRODUCT((평가!C12:P12<>"")*(평가!C24:P24<>"")*(평가!C12:P12=평가!C24:P24))/SUMPRODUCT((평가!C12:P12<>"")*(평가!C24:P24<>"")),"") | U11: =IFERROR(SUMPRODUCT((평가!C12:P12<>"")*(평가!C25:P25<>"")*(평가!C12:P12=평가!C25:P25))/SUMPRODUCT((평가!C12:P12<>"")*(평가!C25:P25<>"")),"") | V11: =IFERROR(SUMPRODUCT((평가!C12:P12<>"")*(평가!C26:P26<>"")*(평가!C12:P12=평가!C26:P26))/SUMPRODUCT((평가!C12:P12<>"")*(평가!C26:P26<>"")),"") | W11: =IFERROR(SUMPRODUCT((평가!C12:P12<>"")*(평가!C27:P27<>"")*(평가!C12:P12=평가!C27:P27))/SUMPRODUCT((평가!C12:P12<>"")*(평가!C27:P27<>"")),"") | X11: =IFERROR(SUMPRODUCT((평가!C12:P12<>"")*(평가!C28:P28<>"")*(평가!C12:P12=평가!C28:P28))/SUMPRODUCT((평가!C12:P12<>"")*(평가!C28:P28<>"")),"") | Y11: =IFERROR(SUMPRODUCT((평가!C12:P12<>"")*(평가!C29:P29<>"")*(평가!C12:P12=평가!C29:P29))/SUMPRODUCT((평가!C12:P12<>"")*(평가!C29:P29<>"")),"")
A12: 조선해양공학과 | B12: =IFERROR(SUMPRODUCT((평가!C13:P13<>"")*(평가!C6:P6<>"")*(평가!C13:P13=평가!C6:P6))/SUMPRODUCT((평가!C13:P13<>"")*(평가!C6:P6<>"")),"") | C12: =IFERROR(SUMPRODUCT((평가!C13:P13<>"")*(평가!C7:P7<>"")*(평가!C13:P13=평가!C7:P7))/SUMPRODUCT((평가!C13:P13<>"")*(평가!C7:P7<>"")),"") | D12: =IFERROR(SUMPRODUCT((평가!C13:P13<>"")*(평가!C8:P8<>"")*(평가!C13:P13=평가!C8:P8))/SUMPRODUCT((평가!C13:P13<>"")*(평가!C8:P8<>"")),"") | E12: =IFERROR(SUMPRODUCT((평가!C13:P13<>"")*(평가!C9:P9<>"")*(평가!C13:P13=평가!C9:P9))/SUMPRODUCT((평가!C13:P13<>"")*(평가!C9:P9<>"")),"") | F12: =IFERROR(SUMPRODUCT((평가!C13:P13<>"")*(평가!C10:P10<>"")*(평가!C13:P13=평가!C10:P10))/SUMPRODUCT((평가!C13:P13<>"")*(평가!C10:P10<>"")),"") | G12: =IFERROR(SUMPRODUCT((평가!C13:P13<>"")*(평가!C11:P11<>"")*(평가!C13:P13=평가!C11:P11))/SUMPRODUCT((평가!C13:P13<>"")*(평가!C11:P11<>"")),"") | H12: =IFERROR(SUMPRODUCT((평가!C13:P13<>"")*(평가!C12:P12<>"")*(평가!C13:P13=평가!C12:P12))/SUMPRODUCT((평가!C13:P13<>"")*(평가!C12:P12<>"")),"") | I12: ="-" | J12: =IFERROR(SUMPRODUCT((평가!C13:P13<>"")*(평가!C14:P14<>"")*(평가!C13:P13=평가!C14:P14))/SUMPRODUCT((평가!C13:P13<>"")*(평가!C14:P14<>"")),"") | K12: =IFERROR(SUMPRODUCT((평가!C13:P13<>"")*(평가!C15:P15<>"")*(평가!C13:P13=평가!C15:P15))/SUMPRODUCT((평가!C13:P13<>"")*(평가!C15:P15<>"")),"") | L12: =IFERROR(SUMPRODUCT((평가!C13:P13<>"")*(평가!C16:P16<>"")*(평가!C13:P13=평가!C16:P16))/SUMPRODUCT((평가!C13:P13<>"")*(평가!C16:P16<>"")),"") | M12: =IFERROR(SUMPRODUCT((평가!C13:P13<>"")*(평가!C17:P17<>"")*(평가!C13:P13=평가!C17:P17))/SUMPRODUCT((평가!C13:P13<>"")*(평가!C17:P17<>"")),"") | N12: =IFERROR(SUMPRODUCT((평가!C13:P13<>"")*(평가!C18:P18<>"")*(평가!C13:P13=평가!C18:P18))/SUMPRODUCT((평가!C13:P13<>"")*(평가!C18:P18<>"")),"") | O12: =IFERROR(SUMPRODUCT((평가!C13:P13<>"")*(평가!C19:P19<>"")*(평가!C13:P13=평가!C19:P19))/SUMPRODUCT((평가!C13:P13<>"")*(평가!C19:P19<>"")),"") | P12: =IFERROR(SUMPRODUCT((평가!C13:P13<>"")*(평가!C20:P20<>"")*(평가!C13:P13=평가!C20:P20))/SUMPRODUCT((평가!C13:P13<>"")*(평가!C20:P20<>"")),"") | Q12: =IFERROR(SUMPRODUCT((평가!C13:P13<>"")*(평가!C21:P21<>"")*(평가!C13:P13=평가!C21:P21))/SUMPRODUCT((평가!C13:P13<>"")*(평가!C21:P21<>"")),"") | R12: =IFERROR(SUMPRODUCT((평가!C13:P13<>"")*(평가!C22:P22<>"")*(평가!C13:P13=평가!C22:P22))/SUMPRODUCT((평가!C13:P13<>"")*(평가!C22:P22<>"")),"") | S12: =IFERROR(SUMPRODUCT((평가!C13:P13<>"")*(평가!C23:P23<>"")*(평가!C13:P13=평가!C23:P23))/SUMPRODUCT((평가!C13:P13<>"")*(평가!C23:P23<>"")),"") | T12: =IFERROR(SUMPRODUCT((평가!C13:P13<>"")*(평가!C24:P24<>"")*(평가!C13:P13=평가!C24:P24))/SUMPRODUCT((평가!C13:P13<>"")*(평가!C24:P24<>"")),"") | U12: =IFERROR(SUMPRODUCT((평가!C13:P13<>"")*(평가!C25:P25<>"")*(평가!C13:P13=평가!C25:P25))/SUMPRODUCT((평가!C13:P13<>"")*(평가!C25:P25<>"")),"") | V12: =IFERROR(SUMPRODUCT((평가!C13:P13<>"")*(평가!C26:P26<>"")*(평가!C13:P13=평가!C26:P26))/SUMPRODUCT((평가!C13:P13<>"")*(평가!C26:P26<>"")),"") | W12: =IFERROR(SUMPRODUCT((평가!C13:P13<>"")*(평가!C27:P27<>"")*(평가!C13:P13=평가!C27:P27))/SUMPRODUCT((평가!C13:P13<>"")*(평가!C27:P27<>"")),"") | X12: =IFERROR(SUMPRODUCT((평가!C13:P13<>"")*(평가!C28:P28<>"")*(평가!C13:P13=평가!C28:P28))/SUMPRODUCT((평가!C13:P13<>"")*(평가!C28:P28<>"")),"") | Y12: =IFERROR(SUMPRODUCT((평가!C13:P13<>"")*(평가!C29:P29<>"")*(평가!C13:P13=평가!C29:P29))/SUMPRODUCT((평가!C13:P13<>"")*(평가!C29:P29<>"")),"")
A13: 의예과 | B13: =IFERROR(SUMPRODUCT((평가!C14:P14<>"")*(평가!C6:P6<>"")*(평가!C14:P14=평가!C6:P6))/SUMPRODUCT((평가!C14:P14<>"")*(평가!C6:P6<>"")),"") | C13: =IFERROR(SUMPRODUCT((평가!C14:P14<>"")*(평가!C7:P7<>"")*(평가!C14:P14=평가!C7:P7))/SUMPRODUCT((평가!C14:P14<>"")*(평가!C7:P7<>"")),"") | D13: =IFERROR(SUMPRODUCT((평가!C14:P14<>"")*(평가!C8:P8<>"")*(평가!C14:P14=평가!C8:P8))/SUMPRODUCT((평가!C14:P14<>"")*(평가!C8:P8<>"")),"") | E13: =IFERROR(SUMPRODUCT((평가!C14:P14<>"")*(평가!C9:P9<>"")*(평가!C14:P14=평가!C9:P9))/SUMPRODUCT((평가!C14:P14<>"")*(평가!C9:P9<>"")),"") | F13: =IFERROR(SUMPRODUCT((평가!C14:P14<>"")*(평가!C10:P10<>"")*(평가!C14:P14=평가!C10:P10))/SUMPRODUCT((평가!C14:P14<>"")*(평가!C10:P10<>"")),"") | G13: =IFERROR(SUMPRODUCT((평가!C14:P14<>"")*(평가!C11:P11<>"")*(평가!C14:P14=평가!C11:P11))/SUMPRODUCT((평가!C14:P14<>"")*(평가!C11:P11<>"")),"") | H13: =IFERROR(SUMPRODUCT((평가!C14:P14<>"")*(평가!C12:P12<>"")*(평가!C14:P14=평가!C12:P12))/SUMPRODUCT((평가!C14:P14<>"")*(평가!C12:P12<>"")),"") | I13: =IFERROR(SUMPRODUCT((평가!C14:P14<>"")*(평가!C13:P13<>"")*(평가!C14:P14=평가!C13:P13))/SUMPRODUCT((평가!C14:P14<>"")*(평가!C13:P13<>"")),"") | J13: ="-" | K13: =IFERROR(SUMPRODUCT((평가!C14:P14<>"")*(평가!C15:P15<>"")*(평가!C14:P14=평가!C15:P15))/SUMPRODUCT((평가!C14:P14<>"")*(평가!C15:P15<>"")),"") | L13: =IFERROR(SUMPRODUCT((평가!C14:P14<>"")*(평가!C16:P16<>"")*(평가!C14:P14=평가!C16:P16))/SUMPRODUCT((평가!C14:P14<>"")*(평가!C16:P16<>"")),"") | M13: =IFERROR(SUMPRODUCT((평가!C14:P14<>"")*(평가!C17:P17<>"")*(평가!C14:P14=평가!C17:P17))/SUMPRODUCT((평가!C14:P14<>"")*(평가!C17:P17<>"")),"") | N13: =IFERROR(SUMPRODUCT((평가!C14:P14<>"")*(평가!C18:P18<>"")*(평가!C14:P14=평가!C18:P18))/SUMPRODUCT((평가!C14:P14<>"")*(평가!C18:P18<>"")),"") | O13: =IFERROR(SUMPRODUCT((평가!C14:P14<>"")*(평가!C19:P19<>"")*(평가!C14:P14=평가!C19:P19))/SUMPRODUCT((평가!C14:P14<>"")*(평가!C19:P19<>"")),"") | P13: =IFERROR(SUMPRODUCT((평가!C14:P14<>"")*(평가!C20:P20<>"")*(평가!C14:P14=평가!C20:P20))/SUMPRODUCT((평가!C14:P14<>"")*(평가!C20:P20<>"")),"") | Q13: =IFERROR(SUMPRODUCT((평가!C14:P14<>"")*(평가!C21:P21<>"")*(평가!C14:P14=평가!C21:P21))/SUMPRODUCT((평가!C14:P14<>"")*(평가!C21:P21<>"")),"") | R13: =IFERROR(SUMPRODUCT((평가!C14:P14<>"")*(평가!C22:P22<>"")*(평가!C14:P14=평가!C22:P22))/SUMPRODUCT((평가!C14:P14<>"")*(평가!C22:P22<>"")),"") | S13: =IFERROR(SUMPRODUCT((평가!C14:P14<>"")*(평가!C23:P23<>"")*(평가!C14:P14=평가!C23:P23))/SUMPRODUCT((평가!C14:P14<>"")*(평가!C23:P23<>"")),"") | T13: =IFERROR(SUMPRODUCT((평가!C14:P14<>"")*(평가!C24:P24<>"")*(평가!C14:P14=평가!C24:P24))/SUMPRODUCT((평가!C14:P14<>"")*(평가!C24:P24<>"")),"") | U13: =IFERROR(SUMPRODUCT((평가!C14:P14<>"")*(평가!C25:P25<>"")*(평가!C14:P14=평가!C25:P25))/SUMPRODUCT((평가!C14:P14<>"")*(평가!C25:P25<>"")),"") | V13: =IFERROR(SUMPRODUCT((평가!C14:P14<>"")*(평가!C26:P26<>"")*(평가!C14:P14=평가!C26:P26))/SUMPRODUCT((평가!C14:P14<>"")*(평가!C26:P26<>"")),"") | W13: =IFERROR(SUMPRODUCT((평가!C14:P14<>"")*(평가!C27:P27<>"")*(평가!C14:P14=평가!C27:P27))/SUMPRODUCT((평가!C14:P14<>"")*(평가!C27:P27<>"")),"") | X13: =IFERROR(SUMPRODUCT((평가!C14:P14<>"")*(평가!C28:P28<>"")*(평가!C14:P14=평가!C28:P28))/SUMPRODUCT((평가!C14:P14<>"")*(평가!C28:P28<>"")),"") | Y13: =IFERROR(SUMPRODUCT((평가!C14:P14<>"")*(평가!C29:P29<>"")*(평가!C14:P14=평가!C29:P29))/SUMPRODUCT((평가!C14:P14<>"")*(평가!C29:P29<>"")),"")
A14: 수학과 | B14: =IFERROR(SUMPRODUCT((평가!C15:P15<>"")*(평가!C6:P6<>"")*(평가!C15:P15=평가!C6:P6))/SUMPRODUCT((평가!C15:P15<>"")*(평가!C6:P6<>"")),"") | C14: =IFERROR(SUMPRODUCT((평가!C15:P15<>"")*(평가!C7:P7<>"")*(평가!C15:P15=평가!C7:P7))/SUMPRODUCT((평가!C15:P15<>"")*(평가!C7:P7<>"")),"") | D14: =IFERROR(SUMPRODUCT((평가!C15:P15<>"")*(평가!C8:P8<>"")*(평가!C15:P15=평가!C8:P8))/SUMPRODUCT((평가!C15:P15<>"")*(평가!C8:P8<>"")),"") | E14: =IFERROR(SUMPRODUCT((평가!C15:P15<>"")*(평가!C9:P9<>"")*(평가!C15:P15=평가!C9:P9))/SUMPRODUCT((평가!C15:P15<>"")*(평가!C9:P9<>"")),"") | F14: =IFERROR(SUMPRODUCT((평가!C15:P15<>"")*(평가!C10:P10<>"")*(평가!C15:P15=평가!C10:P10))/SUMPRODUCT((평가!C15:P15<>"")*(평가!C10:P10<>"")),"") | G14: =IFERROR(SUMPRODUCT((평가!C15:P15<>"")*(평가!C11:P11<>"")*(평가!C15:P15=평가!C11:P11))/SUMPRODUCT((평가!C15:P15<>"")*(평가!C11:P11<>"")),"") | H14: =IFERROR(SUMPRODUCT((평가!C15:P15<>"")*(평가!C12:P12<>"")*(평가!C15:P15=평가!C12:P12))/SUMPRODUCT((평가!C15:P15<>"")*(평가!C12:P12<>"")),"") | I14: =IFERROR(SUMPRODUCT((평가!C15:P15<>"")*(평가!C13:P13<>"")*(평가!C15:P15=평가!C13:P13))/SUMPRODUCT((평가!C15:P15<>"")*(평가!C13:P13<>"")),"") | J14: =IFERROR(SUMPRODUCT((평가!C15:P15<>"")*(평가!C14:P14<>"")*(평가!C15:P15=평가!C14:P14))/SUMPRODUCT((평가!C15:P15<>"")*(평가!C14:P14<>"")),"") | K14: ="-" | L14: =IFERROR(SUMPRODUCT((평가!C15:P15<>"")*(평가!C16:P16<>"")*(평가!C15:P15=평가!C16:P16))/SUMPRODUCT((평가!C15:P15<>"")*(평가!C16:P16<>"")),"") | M14: =IFERROR(SUMPRODUCT((평가!C15:P15<>"")*(평가!C17:P17<>"")*(평가!C15:P15=평가!C17:P17))/SUMPRODUCT((평가!C15:P15<>"")*(평가!C17:P17<>"")),"") | N14: =IFERROR(SUMPRODUCT((평가!C15:P15<>"")*(평가!C18:P18<>"")*(평가!C15:P15=평가!C18:P18))/SUMPRODUCT((평가!C15:P15<>"")*(평가!C18:P18<>"")),"") | O14: =IFERROR(SUMPRODUCT((평가!C15:P15<>"")*(평가!C19:P19<>"")*(평가!C15:P15=평가!C19:P19))/SUMPRODUCT((평가!C15:P15<>"")*(평가!C19:P19<>"")),"") | P14: =IFERROR(SUMPRODUCT((평가!C15:P15<>"")*(평가!C20:P20<>"")*(평가!C15:P15=평가!C20:P20))/SUMPRODUCT((평가!C15:P15<>"")*(평가!C20:P20<>"")),"") | Q14: =IFERROR(SUMPRODUCT((평가!C15:P15<>"")*(평가!C21:P21<>"")*(평가!C15:P15=평가!C21:P21))/SUMPRODUCT((평가!C15:P15<>"")*(평가!C21:P21<>"")),"") | R14: =IFERROR(SUMPRODUCT((평가!C15:P15<>"")*(평가!C22:P22<>"")*(평가!C15:P15=평가!C22:P22))/SUMPRODUCT((평가!C15:P15<>"")*(평가!C22:P22<>"")),"") | S14: =IFERROR(SUMPRODUCT((평가!C15:P15<>"")*(평가!C23:P23<>"")*(평가!C15:P15=평가!C23:P23))/SUMPRODUCT((평가!C15:P15<>"")*(평가!C23:P23<>"")),"") | T14: =IFERROR(SUMPRODUCT((평가!C15:P15<>"")*(평가!C24:P24<>"")*(평가!C15:P15=평가!C24:P24))/SUMPRODUCT((평가!C15:P15<>"")*(평가!C24:P24<>"")),"") | U14: =IFERROR(SUMPRODUCT((평가!C15:P15<>"")*(평가!C25:P25<>"")*(평가!C15:P15=평가!C25:P25))/SUMPRODUCT((평가!C15:P15<>"")*(평가!C25:P25<>"")),"") | V14: =IFERROR(SUMPRODUCT((평가!C15:P15<>"")*(평가!C26:P26<>"")*(평가!C15:P15=평가!C26:P26))/SUMPRODUCT((평가!C15:P15<>"")*(평가!C26:P26<>"")),"") | W14: =IFERROR(SUMPRODUCT((평가!C15:P15<>"")*(평가!C27:P27<>"")*(평가!C15:P15=평가!C27:P27))/SUMPRODUCT((평가!C15:P15<>"")*(평가!C27:P27<>"")),"") | X14: =IFERROR(SUMPRODUCT((평가!C15:P15<>"")*(평가!C28:P28<>"")*(평가!C15:P15=평가!C28:P28))/SUMPRODUCT((평가!C15:P15<>"")*(평가!C28:P28<>"")),"") | Y14: =IFERROR(SUMPRODUCT((평가!C15:P15<>"")*(평가!C29:P29<>"")*(평가!C15:P15=평가!C29:P29))/SUMPRODUCT((평가!C15:P15<>"")*(평가!C29:P29<>"")),"")
A15: 경영학과 | B15: =IFERROR(SUMPRODUCT((평가!C16:P16<>"")*(평가!C6:P6<>"")*(평가!C16:P16=평가!C6:P6))/SUMPRODUCT((평가!C16:P16<>"")*(평가!C6:P6<>"")),"") | C15: =IFERROR(SUMPRODUCT((평가!C16:P16<>"")*(평가!C7:P7<>"")*(평가!C16:P16=평가!C7:P7))/SUMPRODUCT((평가!C16:P16<>"")*(평가!C7:P7<>"")),"") | D15: =IFERROR(SUMPRODUCT((평가!C16:P16<>"")*(평가!C8:P8<>"")*(평가!C16:P16=평가!C8:P8))/SUMPRODUCT((평가!C16:P16<>"")*(평가!C8:P8<>"")),"") | E15: =IFERROR(SUMPRODUCT((평가!C16:P16<>"")*(평가!C9:P9<>"")*(평가!C16:P16=평가!C9:P9))/SUMPRODUCT((평가!C16:P16<>"")*(평가!C9:P9<>"")),"") | F15: =IFERROR(SUMPRODUCT((평가!C16:P16<>"")*(평가!C10:P10<>"")*(평가!C16:P16=평가!C10:P10))/SUMPRODUCT((평가!C16:P16<>"")*(평가!C10:P10<>"")),"") | G15: =IFERROR(SUMPRODUCT((평가!C16:P16<>"")*(평가!C11:P11<>"")*(평가!C16:P16=평가!C11:P11))/SUMPRODUCT((평가!C16:P16<>"")*(평가!C11:P11<>"")),"") | H15: =IFERROR(SUMPRODUCT((평가!C16:P16<>"")*(평가!C12:P12<>"")*(평가!C16:P16=평가!C12:P12))/SUMPRODUCT((평가!C16:P16<>"")*(평가!C12:P12<>"")),"") | I15: =IFERROR(SUMPRODUCT((평가!C16:P16<>"")*(평가!C13:P13<>"")*(평가!C16:P16=평가!C13:P13))/SUMPRODUCT((평가!C16:P16<>"")*(평가!C13:P13<>"")),"") | J15: =IFERROR(SUMPRODUCT((평가!C16:P16<>"")*(평가!C14:P14<>"")*(평가!C16:P16=평가!C14:P14))/SUMPRODUCT((평가!C16:P16<>"")*(평가!C14:P14<>"")),"") | K15: =IFERROR(SUMPRODUCT((평가!C16:P16<>"")*(평가!C15:P15<>"")*(평가!C16:P16=평가!C15:P15))/SUMPRODUCT((평가!C16:P16<>"")*(평가!C15:P15<>"")),"") | L15: ="-" | M15: =IFERROR(SUMPRODUCT((평가!C16:P16<>"")*(평가!C17:P17<>"")*(평가!C16:P16=평가!C17:P17))/SUMPRODUCT((평가!C16:P16<>"")*(평가!C17:P17<>"")),"") | N15: =IFERROR(SUMPRODUCT((평가!C16:P16<>"")*(평가!C18:P18<>"")*(평가!C16:P16=평가!C18:P18))/SUMPRODUCT((평가!C16:P16<>"")*(평가!C18:P18<>"")),"") | O15: =IFERROR(SUMPRODUCT((평가!C16:P16<>"")*(평가!C19:P19<>"")*(평가!C16:P16=평가!C19:P19))/SUMPRODUCT((평가!C16:P16<>"")*(평가!C19:P19<>"")),"") | P15: =IFERROR(SUMPRODUCT((평가!C16:P16<>"")*(평가!C20:P20<>"")*(평가!C16:P16=평가!C20:P20))/SUMPRODUCT((평가!C16:P16<>"")*(평가!C20:P20<>"")),"") | Q15: =IFERROR(SUMPRODUCT((평가!C16:P16<>"")*(평가!C21:P21<>"")*(평가!C16:P16=평가!C21:P21))/SUMPRODUCT((평가!C16:P16<>"")*(평가!C21:P21<>"")),"") | R15: =IFERROR(SUMPRODUCT((평가!C16:P16<>"")*(평가!C22:P22<>"")*(평가!C16:P16=평가!C22:P22))/SUMPRODUCT((평가!C16:P16<>"")*(평가!C22:P22<>"")),"") | S15: =IFERROR(SUMPRODUCT((평가!C16:P16<>"")*(평가!C23:P23<>"")*(평가!C16:P16=평가!C23:P23))/SUMPRODUCT((평가!C16:P16<>"")*(평가!C23:P23<>"")),"") | T15: =IFERROR(SUMPRODUCT((평가!C16:P16<>"")*(평가!C24:P24<>"")*(평가!C16:P16=평가!C24:P24))/SUMPRODUCT((평가!C16:P16<>"")*(평가!C24:P24<>"")),"") | U15: =IFERROR(SUMPRODUCT((평가!C16:P16<>"")*(평가!C25:P25<>"")*(평가!C16:P16=평가!C25:P25))/SUMPRODUCT((평가!C16:P16<>"")*(평가!C25:P25<>"")),"") | V15: =IFERROR(SUMPRODUCT((평가!C16:P16<>"")*(평가!C26:P26<>"")*(평가!C16:P16=평가!C26:P26))/SUMPRODUCT((평가!C16:P16<>"")*(평가!C26:P26<>"")),"") | W15: =IFERROR(SUMPRODUCT((평가!C16:P16<>"")*(평가!C27:P27<>"")*(평가!C16:P16=평가!C27:P27))/SUMPRODUCT((평가!C16:P16<>"")*(평가!C27:P27<>"")),"") | X15: =IFERROR(SUMPRODUCT((평가!C16:P16<>"")*(평가!C28:P28<>"")*(평가!C16:P16=평가!C28:P28))/SUMPRODUCT((평가!C16:P16<>"")*(평가!C28:P28<>"")),"") | Y15: =IFERROR(SUMPRODUCT((평가!C16:P16<>"")*(평가!C29:P29<>"")*(평가!C16:P16=평가!C29:P29))/SUMPRODUCT((평가!C16:P16<>"")*(평가!C29:P29<>"")),"")
A16: 약학과 | B16: =IFERROR(SUMPRODUCT((평가!C17:P17<>"")*(평가!C6:P6<>"")*(평가!C17:P17=평가!C6:P6))/SUMPRODUCT((평가!C17:P17<>"")*(평가!C6:P6<>"")),"") | C16: =IFERROR(SUMPRODUCT((평가!C17:P17<>"")*(평가!C7:P7<>"")*(평가!C17:P17=평가!C7:P7))/SUMPRODUCT((평가!C17:P17<>"")*(평가!C7:P7<>"")),"") | D16: =IFERROR(SUMPRODUCT((평가!C17:P17<>"")*(평가!C8:P8<>"")*(평가!C17:P17=평가!C8:P8))/SUMPRODUCT((평가!C17:P17<>"")*(평가!C8:P8<>"")),"") | E16: =IFERROR(SUMPRODUCT((평가!C17:P17<>"")*(평가!C9:P9<>"")*(평가!C17:P17=평가!C9:P9))/SUMPRODUCT((평가!C17:P17<>"")*(평가!C9:P9<>"")),"") | F16: =IFERROR(SUMPRODUCT((평가!C17:P17<>"")*(평가!C10:P10<>"")*(평가!C17:P17=평가!C10:P10))/SUMPRODUCT((평가!C17:P17<>"")*(평가!C10:P10<>"")),"") | G16: =IFERROR(SUMPRODUCT((평가!C17:P17<>"")*(평가!C11:P11<>"")*(평가!C17:P17=평가!C11:P11))/SUMPRODUCT((평가!C17:P17<>"")*(평가!C11:P11<>"")),"") | H16: =IFERROR(SUMPRODUCT((평가!C17:P17<>"")*(평가!C12:P12<>"")*(평가!C17:P17=평가!C12:P12))/SUMPRODUCT((평가!C17:P17<>"")*(평가!C12:P12<>"")),"") | I16: =IFERROR(SUMPRODUCT((평가!C17:P17<>"")*(평가!C13:P13<>"")*(평가!C17:P17=평가!C13:P13))/SUMPRODUCT((평가!C17:P17<>"")*(평가!C13:P13<>"")),"") | J16: =IFERROR(SUMPRODUCT((평가!C17:P17<>"")*(평가!C14:P14<>"")*(평가!C17:P17=평가!C14:P14))/SUMPRODUCT((평가!C17:P17<>"")*(평가!C14:P14<>"")),"") | K16: =IFERROR(SUMPRODUCT((평가!C17:P17<>"")*(평가!C15:P15<>"")*(평가!C17:P17=평가!C15:P15))/SUMPRODUCT((평가!C17:P17<>"")*(평가!C15:P15<>"")),"") | L16: =IFERROR(SUMPRODUCT((평가!C17:P17<>"")*(평가!C16:P16<>"")*(평가!C17:P17=평가!C16:P16))/SUMPRODUCT((평가!C17:P17<>"")*(평가!C16:P16<>"")),"") | M16: ="-" | N16: =IFERROR(SUMPRODUCT((평가!C17:P17<>"")*(평가!C18:P18<>"")*(평가!C17:P17=평가!C18:P18))/SUMPRODUCT((평가!C17:P17<>"")*(평가!C18:P18<>"")),"") | O16: =IFERROR(SUMPRODUCT((평가!C17:P17<>"")*(평가!C19:P19<>"")*(평가!C17:P17=평가!C19:P19))/SUMPRODUCT((평가!C17:P17<>"")*(평가!C19:P19<>"")),"") | P16: =IFERROR(SUMPRODUCT((평가!C17:P17<>"")*(평가!C20:P20<>"")*(평가!C17:P17=평가!C20:P20))/SUMPRODUCT((평가!C17:P17<>"")*(평가!C20:P20<>"")),"") | Q16: =IFERROR(SUMPRODUCT((평가!C17:P17<>"")*(평가!C21:P21<>"")*(평가!C17:P17=평가!C21:P21))/SUMPRODUCT((평가!C17:P17<>"")*(평가!C21:P21<>"")),"") | R16: =IFERROR(SUMPRODUCT((평가!C17:P17<>"")*(평가!C22:P22<>"")*(평가!C17:P17=평가!C22:P22))/SUMPRODUCT((평가!C17:P17<>"")*(평가!C22:P22<>"")),"") | S16: =IFERROR(SUMPRODUCT((평가!C17:P17<>"")*(평가!C23:P23<>"")*(평가!C17:P17=평가!C23:P23))/SUMPRODUCT((평가!C17:P17<>"")*(평가!C23:P23<>"")),"") | T16: =IFERROR(SUMPRODUCT((평가!C17:P17<>"")*(평가!C24:P24<>"")*(평가!C17:P17=평가!C24:P24))/SUMPRODUCT((평가!C17:P17<>"")*(평가!C24:P24<>"")),"") | U16: =IFERROR(SUMPRODUCT((평가!C17:P17<>"")*(평가!C25:P25<>"")*(평가!C17:P17=평가!C25:P25))/SUMPRODUCT((평가!C17:P17<>"")*(평가!C25:P25<>"")),"") | V16: =IFERROR(SUMPRODUCT((평가!C17:P17<>"")*(평가!C26:P26<>"")*(평가!C17:P17=평가!C26:P26))/SUMPRODUCT((평가!C17:P17<>"")*(평가!C26:P26<>"")),"") | W16: =IFERROR(SUMPRODUCT((평가!C17:P17<>"")*(평가!C27:P27<>"")*(평가!C17:P17=평가!C27:P27))/SUMPRODUCT((평가!C17:P17<>"")*(평가!C27:P27<>"")),"") | X16: =IFERROR(SUMPRODUCT((평가!C17:P17<>"")*(평가!C28:P28<>"")*(평가!C17:P17=평가!C28:P28))/SUMPRODUCT((평가!C17:P17<>"")*(평가!C28:P28<>"")),"") | Y16: =IFERROR(SUMPRODUCT((평가!C17:P17<>"")*(평가!C29:P29<>"")*(평가!C17:P17=평가!C29:P29))/SUMPRODUCT((평가!C17:P17<>"")*(평가!C29:P29<>"")),"")
A17: 사회학과 | B17: =IFERROR(SUMPRODUCT((평가!C18:P18<>"")*(평가!C6:P6<>"")*(평가!C18:P18=평가!C6:P6))/SUMPRODUCT((평가!C18:P18<>"")*(평가!C6:P6<>"")),"") | C17: =IFERROR(SUMPRODUCT((평가!C18:P18<>"")*(평가!C7:P7<>"")*(평가!C18:P18=평가!C7:P7))/SUMPRODUCT((평가!C18:P18<>"")*(평가!C7:P7<>"")),"") | D17: =IFERROR(SUMPRODUCT((평가!C18:P18<>"")*(평가!C8:P8<>"")*(평가!C18:P18=평가!C8:P8))/SUMPRODUCT((평가!C18:P18<>"")*(평가!C8:P8<>"")),"") | E17: =IFERROR(SUMPRODUCT((평가!C18:P18<>"")*(평가!C9:P9<>"")*(평가!C18:P18=평가!C9:P9))/SUMPRODUCT((평가!C18:P18<>"")*(평가!C9:P9<>"")),"") | F17: =IFERROR(SUMPRODUCT((평가!C18:P18<>"")*(평가!C10:P10<>"")*(평가!C18:P18=평가!C10:P10))/SUMPRODUCT((평가!C18:P18<>"")*(평가!C10:P10<>"")),"") | G17: =IFERROR(SUMPRODUCT((평가!C18:P18<>"")*(평가!C11:P11<>"")*(평가!C18:P18=평가!C11:P11))/SUMPRODUCT((평가!C18:P18<>"")*(평가!C11:P11<>"")),"") | H17: =IFERROR(SUMPRODUCT((평가!C18:P18<>"")*(평가!C12:P12<>"")*(평가!C18:P18=평가!C12:P12))/SUMPRODUCT((평가!C18:P18<>"")*(평가!C12:P12<>"")),"") | I17: =IFERROR(SUMPRODUCT((평가!C18:P18<>"")*(평가!C13:P13<>"")*(평가!C18:P18=평가!C13:P13))/SUMPRODUCT((평가!C18:P18<>"")*(평가!C13:P13<>"")),"") | J17: =IFERROR(SUMPRODUCT((평가!C18:P18<>"")*(평가!C14:P14<>"")*(평가!C18:P18=평가!C14:P14))/SUMPRODUCT((평가!C18:P18<>"")*(평가!C14:P14<>"")),"") | K17: =IFERROR(SUMPRODUCT((평가!C18:P18<>"")*(평가!C15:P15<>"")*(평가!C18:P18=평가!C15:P15))/SUMPRODUCT((평가!C18:P18<>"")*(평가!C15:P15<>"")),"") | L17: =IFERROR(SUMPRODUCT((평가!C18:P18<>"")*(평가!C16:P16<>"")*(평가!C18:P18=평가!C16:P16))/SUMPRODUCT((평가!C18:P18<>"")*(평가!C16:P16<>"")),"") | M17: =IFERROR(SUMPRODUCT((평가!C18:P18<>"")*(평가!C17:P17<>"")*(평가!C18:P18=평가!C17:P17))/SUMPRODUCT((평가!C18:P18<>"")*(평가!C17:P17<>"")),"") | N17: ="-" | O17: =IFERROR(SUMPRODUCT((평가!C18:P18<>"")*(평가!C19:P19<>"")*(평가!C18:P18=평가!C19:P19))/SUMPRODUCT((평가!C18:P18<>"")*(평가!C19:P19<>"")),"") | P17: =IFERROR(SUMPRODUCT((평가!C18:P18<>"")*(평가!C20:P20<>"")*(평가!C18:P18=평가!C20:P20))/SUMPRODUCT((평가!C18:P18<>"")*(평가!C20:P20<>"")),"") | Q17: =IFERROR(SUMPRODUCT((평가!C18:P18<>"")*(평가!C21:P21<>"")*(평가!C18:P18=평가!C21:P21))/SUMPRODUCT((평가!C18:P18<>"")*(평가!C21:P21<>"")),"") | R17: =IFERROR(SUMPRODUCT((평가!C18:P18<>"")*(평가!C22:P22<>"")*(평가!C18:P18=평가!C22:P22))/SUMPRODUCT((평가!C18:P18<>"")*(평가!C22:P22<>"")),"") | S17: =IFERROR(SUMPRODUCT((평가!C18:P18<>"")*(평가!C23:P23<>"")*(평가!C18:P18=평가!C23:P23))/SUMPRODUCT((평가!C18:P18<>"")*(평가!C23:P23<>"")),"") | T17: =IFERROR(SUMPRODUCT((평가!C18:P18<>"")*(평가!C24:P24<>"")*(평가!C18:P18=평가!C24:P24))/SUMPRODUCT((평가!C18:P18<>"")*(평가!C24:P24<>"")),"") | U17: =IFERROR(SUMPRODUCT((평가!C18:P18<>"")*(평가!C25:P25<>"")*(평가!C18:P18=평가!C25:P25))/SUMPRODUCT((평가!C18:P18<>"")*(평가!C25:P25<>"")),"") | V17: =IFERROR(SUMPRODUCT((평가!C18:P18<>"")*(평가!C26:P26<>"")*(평가!C18:P18=평가!C26:P26))/SUMPRODUCT((평가!C18:P18<>"")*(평가!C26:P26<>"")),"") | W17: =IFERROR(SUMPRODUCT((평가!C18:P18<>"")*(평가!C27:P27<>"")*(평가!C18:P18=평가!C27:P27))/SUMPRODUCT((평가!C18:P18<>"")*(평가!C27:P27<>"")),"") | X17: =IFERROR(SUMPRODUCT((평가!C18:P18<>"")*(평가!C28:P28<>"")*(평가!C18:P18=평가!C28:P28))/SUMPRODUCT((평가!C18:P18<>"")*(평가!C28:P28<>"")),"") | Y17: =IFERROR(SUMPRODUCT((평가!C18:P18<>"")*(평가!C29:P29<>"")*(평가!C18:P18=평가!C29:P29))/SUMPRODUCT((평가!C18:P18<>"")*(평가!C29:P29<>"")),"")
A18: 경제학과 | B18: =IFERROR(SUMPRODUCT((평가!C19:P19<>"")*(평가!C6:P6<>"")*(평가!C19:P19=평가!C6:P6))/SUMPRODUCT((평가!C19:P19<>"")*(평가!C6:P6<>"")),"") | C18: =IFERROR(SUMPRODUCT((평가!C19:P19<>"")*(평가!C7:P7<>"")*(평가!C19:P19=평가!C7:P7))/SUMPRODUCT((평가!C19:P19<>"")*(평가!C7:P7<>"")),"") | D18: =IFERROR(SUMPRODUCT((평가!C19:P19<>"")*(평가!C8:P8<>"")*(평가!C19:P19=평가!C8:P8))/SUMPRODUCT((평가!C19:P19<>"")*(평가!C8:P8<>"")),"") | E18: =IFERROR(SUMPRODUCT((평가!C19:P19<>"")*(평가!C9:P9<>"")*(평가!C19:P19=평가!C9:P9))/SUMPRODUCT((평가!C19:P19<>"")*(평가!C9:P9<>"")),"") | F18: =IFERROR(SUMPRODUCT((평가!C19:P19<>"")*(평가!C10:P10<>"")*(평가!C19:P19=평가!C10:P10))/SUMPRODUCT((평가!C19:P19<>"")*(평가!C10:P10<>"")),"") | G18: =IFERROR(SUMPRODUCT((평가!C19:P19<>"")*(평가!C11:P11<>"")*(평가!C19:P19=평가!C11:P11))/SUMPRODUCT((평가!C19:P19<>"")*(평가!C11:P11<>"")),"") | H18: =IFERROR(SUMPRODUCT((평가!C19:P19<>"")*(평가!C12:P12<>"")*(평가!C19:P19=평가!C12:P12))/SUMPRODUCT((평가!C19:P19<>"")*(평가!C12:P12<>"")),"") | I18: =IFERROR(SUMPRODUCT((평가!C19:P19<>"")*(평가!C13:P13<>"")*(평가!C19:P19=평가!C13:P13))/SUMPRODUCT((평가!C19:P19<>"")*(평가!C13:P13<>"")),"") | J18: =IFERROR(SUMPRODUCT((평가!C19:P19<>"")*(평가!C14:P14<>"")*(평가!C19:P19=평가!C14:P14))/SUMPRODUCT((평가!C19:P19<>"")*(평가!C14:P14<>"")),"") | K18: =IFERROR(SUMPRODUCT((평가!C19:P19<>"")*(평가!C15:P15<>"")*(평가!C19:P19=평가!C15:P15))/SUMPRODUCT((평가!C19:P19<>"")*(평가!C15:P15<>"")),"") | L18: =IFERROR(SUMPRODUCT((평가!C19:P19<>"")*(평가!C16:P16<>"")*(평가!C19:P19=평가!C16:P16))/SUMPRODUCT((평가!C19:P19<>"")*(평가!C16:P16<>"")),"") | M18: =IFERROR(SUMPRODUCT((평가!C19:P19<>"")*(평가!C17:P17<>"")*(평가!C19:P19=평가!C17:P17))/SUMPRODUCT((평가!C19:P19<>"")*(평가!C17:P17<>"")),"") | N18: =IFERROR(SUMPRODUCT((평가!C19:P19<>"")*(평가!C18:P18<>"")*(평가!C19:P19=평가!C18:P18))/SUMPRODUCT((평가!C19:P19<>"")*(평가!C18:P18<>"")),"") | O18: ="-" | P18: =IFERROR(SUMPRODUCT((평가!C19:P19<>"")*(평가!C20:P20<>"")*(평가!C19:P19=평가!C20:P20))/SUMPRODUCT((평가!C19:P19<>"")*(평가!C20:P20<>"")),"") | Q18: =IFERROR(SUMPRODUCT((평가!C19:P19<>"")*(평가!C21:P21<>"")*(평가!C19:P19=평가!C21:P21))/SUMPRODUCT((평가!C19:P19<>"")*(평가!C21:P21<>"")),"") | R18: =IFERROR(SUMPRODUCT((평가!C19:P19<>"")*(평가!C22:P22<>"")*(평가!C19:P19=평가!C22:P22))/SUMPRODUCT((평가!C19:P19<>"")*(평가!C22:P22<>"")),"") | S18: =IFERROR(SUMPRODUCT((평가!C19:P19<>"")*(평가!C23:P23<>"")*(평가!C19:P19=평가!C23:P23))/SUMPRODUCT((평가!C19:P19<>"")*(평가!C23:P23<>"")),"") | T18: =IFERROR(SUMPRODUCT((평가!C19:P19<>"")*(평가!C24:P24<>"")*(평가!C19:P19=평가!C24:P24))/SUMPRODUCT((평가!C19:P19<>"")*(평가!C24:P24<>"")),"") | U18: =IFERROR(SUMPRODUCT((평가!C19:P19<>"")*(평가!C25:P25<>"")*(평가!C19:P19=평가!C25:P25))/SUMPRODUCT((평가!C19:P19<>"")*(평가!C25:P25<>"")),"") | V18: =IFERROR(SUMPRODUCT((평가!C19:P19<>"")*(평가!C26:P26<>"")*(평가!C19:P19=평가!C26:P26))/SUMPRODUCT((평가!C19:P19<>"")*(평가!C26:P26<>"")),"") | W18: =IFERROR(SUMPRODUCT((평가!C19:P19<>"")*(평가!C27:P27<>"")*(평가!C19:P19=평가!C27:P27))/SUMPRODUCT((평가!C19:P19<>"")*(평가!C27:P27<>"")),"") | X18: =IFERROR(SUMPRODUCT((평가!C19:P19<>"")*(평가!C28:P28<>"")*(평가!C19:P19=평가!C28:P28))/SUMPRODUCT((평가!C19:P19<>"")*(평가!C28:P28<>"")),"") | Y18: =IFERROR(SUMPRODUCT((평가!C19:P19<>"")*(평가!C29:P29<>"")*(평가!C19:P19=평가!C29:P29))/SUMPRODUCT((평가!C19:P19<>"")*(평가!C29:P29<>"")),"")
A19: 생명과학과 | B19: =IFERROR(SUMPRODUCT((평가!C20:P20<>"")*(평가!C6:P6<>"")*(평가!C20:P20=평가!C6:P6))/SUMPRODUCT((평가!C20:P20<>"")*(평가!C6:P6<>"")),"") | C19: =IFERROR(SUMPRODUCT((평가!C20:P20<>"")*(평가!C7:P7<>"")*(평가!C20:P20=평가!C7:P7))/SUMPRODUCT((평가!C20:P20<>"")*(평가!C7:P7<>"")),"") | D19: =IFERROR(SUMPRODUCT((평가!C20:P20<>"")*(평가!C8:P8<>"")*(평가!C20:P20=평가!C8:P8))/SUMPRODUCT((평가!C20:P20<>"")*(평가!C8:P8<>"")),"") | E19: =IFERROR(SUMPRODUCT((평가!C20:P20<>"")*(평가!C9:P9<>"")*(평가!C20:P20=평가!C9:P9))/SUMPRODUCT((평가!C20:P20<>"")*(평가!C9:P9<>"")),"") | F19: =IFERROR(SUMPRODUCT((평가!C20:P20<>"")*(평가!C10:P10<>"")*(평가!C20:P20=평가!C10:P10))/SUMPRODUCT((평가!C20:P20<>"")*(평가!C10:P10<>"")),"") | G19: =IFERROR(SUMPRODUCT((평가!C20:P20<>"")*(평가!C11:P11<>"")*(평가!C20:P20=평가!C11:P11))/SUMPRODUCT((평가!C20:P20<>"")*(평가!C11:P11<>"")),"") | H19: =IFERROR(SUMPRODUCT((평가!C20:P20<>"")*(평가!C12:P12<>"")*(평가!C20:P20=평가!C12:P12))/SUMPRODUCT((평가!C20:P20<>"")*(평가!C12:P12<>"")),"") | I19: =IFERROR(SUMPRODUCT((평가!C20:P20<>"")*(평가!C13:P13<>"")*(평가!C20:P20=평가!C13:P13))/SUMPRODUCT((평가!C20:P20<>"")*(평가!C13:P13<>"")),"") | J19: =IFERROR(SUMPRODUCT((평가!C20:P20<>"")*(평가!C14:P14<>"")*(평가!C20:P20=평가!C14:P14))/SUMPRODUCT((평가!C20:P20<>"")*(평가!C14:P14<>"")),"") | K19: =IFERROR(SUMPRODUCT((평가!C20:P20<>"")*(평가!C15:P15<>"")*(평가!C20:P20=평가!C15:P15))/SUMPRODUCT((평가!C20:P20<>"")*(평가!C15:P15<>"")),"") | L19: =IFERROR(SUMPRODUCT((평가!C20:P20<>"")*(평가!C16:P16<>"")*(평가!C20:P20=평가!C16:P16))/SUMPRODUCT((평가!C20:P20<>"")*(평가!C16:P16<>"")),"") | M19: =IFERROR(SUMPRODUCT((평가!C20:P20<>"")*(평가!C17:P17<>"")*(평가!C20:P20=평가!C17:P17))/SUMPRODUCT((평가!C20:P20<>"")*(평가!C17:P17<>"")),"") | N19: =IFERROR(SUMPRODUCT((평가!C20:P20<>"")*(평가!C18:P18<>"")*(평가!C20:P20=평가!C18:P18))/SUMPRODUCT((평가!C20:P20<>"")*(평가!C18:P18<>"")),"") | O19: =IFERROR(SUMPRODUCT((평가!C20:P20<>"")*(평가!C19:P19<>"")*(평가!C20:P20=평가!C19:P19))/SUMPRODUCT((평가!C20:P20<>"")*(평가!C19:P19<>"")),"") | P19: ="-" | Q19: =IFERROR(SUMPRODUCT((평가!C20:P20<>"")*(평가!C21:P21<>"")*(평가!C20:P20=평가!C21:P21))/SUMPRODUCT((평가!C20:P20<>"")*(평가!C21:P21<>"")),"") | R19: =IFERROR(SUMPRODUCT((평가!C20:P20<>"")*(평가!C22:P22<>"")*(평가!C20:P20=평가!C22:P22))/SUMPRODUCT((평가!C20:P20<>"")*(평가!C22:P22<>"")),"") | S19: =IFERROR(SUMPRODUCT((평가!C20:P20<>"")*(평가!C23:P23<>"")*(평가!C20:P20=평가!C23:P23))/SUMPRODUCT((평가!C20:P20<>"")*(평가!C23:P23<>"")),"") | T19: =IFERROR(SUMPRODUCT((평가!C20:P20<>"")*(평가!C24:P24<>"")*(평가!C20:P20=평가!C24:P24))/SUMPRODUCT((평가!C20:P20<>"")*(평가!C24:P24<>"")),"") | U19: =IFERROR(SUMPRODUCT((평가!C20:P20<>"")*(평가!C25:P25<>"")*(평가!C20:P20=평가!C25:P25))/SUMPRODUCT((평가!C20:P20<>"")*(평가!C25:P25<>"")),"") | V19: =IFERROR(SUMPRODUCT((평가!C20:P20<>"")*(평가!C26:P26<>"")*(평가!C20:P20=평가!C26:P26))/SUMPRODUCT((평가!C20:P20<>"")*(평가!C26:P26<>"")),"") | W19: =IFERROR(SUMPRODUCT((평가!C20:P20<>"")*(평가!C27:P27<>"")*(평가!C20:P20=평가!C27:P27))/SUMPRODUCT((평가!C20:P20<>"")*(평가!C27:P27<>"")),"") | X19: =IFERROR(SUMPRODUCT((평가!C20:P20<>"")*(평가!C28:P28<>"")*(평가!C20:P20=평가!C28:P28))/SUMPRODUCT((평가!C20:P20<>"")*(평가!C28:P28<>"")),"") | Y19: =IFERROR(SUMPRODUCT((평가!C20:P20<>"")*(평가!C29:P29<>"")*(평가!C20:P20=평가!C29:P29))/SUMPRODUCT((평가!C20:P20<>"")*(평가!C29:P29<>"")),"")
A20: 미디어커뮤니케이션학과 | B20: =IFERROR(SUMPRODUCT((평가!C21:P21<>"")*(평가!C6:P6<>"")*(평가!C21:P21=평가!C6:P6))/SUMPRODUCT((평가!C21:P21<>"")*(평가!C6:P6<>"")),"") | C20: =IFERROR(SUMPRODUCT((평가!C21:P21<>"")*(평가!C7:P7<>"")*(평가!C21:P21=평가!C7:P7))/SUMPRODUCT((평가!C21:P21<>"")*(평가!C7:P7<>"")),"") | D20: =IFERROR(SUMPRODUCT((평가!C21:P21<>"")*(평가!C8:P8<>"")*(평가!C21:P21=평가!C8:P8))/SUMPRODUCT((평가!C21:P21<>"")*(평가!C8:P8<>"")),"") | E20: =IFERROR(SUMPRODUCT((평가!C21:P21<>"")*(평가!C9:P9<>"")*(평가!C21:P21=평가!C9:P9))/SUMPRODUCT((평가!C21:P21<>"")*(평가!C9:P9<>"")),"") | F20: =IFERROR(SUMPRODUCT((평가!C21:P21<>"")*(평가!C10:P10<>"")*(평가!C21:P21=평가!C10:P10))/SUMPRODUCT((평가!C21:P21<>"")*(평가!C10:P10<>"")),"") | G20: =IFERROR(SUMPRODUCT((평가!C21:P21<>"")*(평가!C11:P11<>"")*(평가!C21:P21=평가!C11:P11))/SUMPRODUCT((평가!C21:P21<>"")*(평가!C11:P11<>"")),"") | H20: =IFERROR(SUMPRODUCT((평가!C21:P21<>"")*(평가!C12:P12<>"")*(평가!C21:P21=평가!C12:P12))/SUMPRODUCT((평가!C21:P21<>"")*(평가!C12:P12<>"")),"") | I20: =IFERROR(SUMPRODUCT((평가!C21:P21<>"")*(평가!C13:P13<>"")*(평가!C21:P21=평가!C13:P13))/SUMPRODUCT((평가!C21:P21<>"")*(평가!C13:P13<>"")),"") | J20: =IFERROR(SUMPRODUCT((평가!C21:P21<>"")*(평가!C14:P14<>"")*(평가!C21:P21=평가!C14:P14))/SUMPRODUCT((평가!C21:P21<>"")*(평가!C14:P14<>"")),"") | K20: =IFERROR(SUMPRODUCT((평가!C21:P21<>"")*(평가!C15:P15<>"")*(평가!C21:P21=평가!C15:P15))/SUMPRODUCT((평가!C21:P21<>"")*(평가!C15:P15<>"")),"") | L20: =IFERROR(SUMPRODUCT((평가!C21:P21<>"")*(평가!C16:P16<>"")*(평가!C21:P21=평가!C16:P16))/SUMPRODUCT((평가!C21:P21<>"")*(평가!C16:P16<>"")),"") | M20: =IFERROR(SUMPRODUCT((평가!C21:P21<>"")*(평가!C17:P17<>"")*(평가!C21:P21=평가!C17:P17))/SUMPRODUCT((평가!C21:P21<>"")*(평가!C17:P17<>"")),"") | N20: =IFERROR(SUMPRODUCT((평가!C21:P21<>"")*(평가!C18:P18<>"")*(평가!C21:P21=평가!C18:P18))/SUMPRODUCT((평가!C21:P21<>"")*(평가!C18:P18<>"")),"") | O20: =IFERROR(SUMPRODUCT((평가!C21:P21<>"")*(평가!C19:P19<>"")*(평가!C21:P21=평가!C19:P19))/SUMPRODUCT((평가!C21:P21<>"")*(평가!C19:P19<>"")),"") | P20: =IFERROR(SUMPRODUCT((평가!C21:P21<>"")*(평가!C20:P20<>"")*(평가!C21:P21=평가!C20:P20))/SUMPRODUCT((평가!C21:P21<>"")*(평가!C20:P20<>"")),"") | Q20: ="-" | R20: =IFERROR(SUMPRODUCT((평가!C21:P21<>"")*(평가!C22:P22<>"")*(평가!C21:P21=평가!C22:P22))/SUMPRODUCT((평가!C21:P21<>"")*(평가!C22:P22<>"")),"") | S20: =IFERROR(SUMPRODUCT((평가!C21:P21<>"")*(평가!C23:P23<>"")*(평가!C21:P21=평가!C23:P23))/SUMPRODUCT((평가!C21:P21<>"")*(평가!C23:P23<>"")),"") | T20: =IFERROR(SUMPRODUCT((평가!C21:P21<>"")*(평가!C24:P24<>"")*(평가!C21:P21=평가!C24:P24))/SUMPRODUCT((평가!C21:P21<>"")*(평가!C24:P24<>"")),"") | U20: =IFERROR(SUMPRODUCT((평가!C21:P21<>"")*(평가!C25:P25<>"")*(평가!C21:P21=평가!C25:P25))/SUMPRODUCT((평가!C21:P21<>"")*(평가!C25:P25<>"")),"") | V20: =IFERROR(SUMPRODUCT((평가!C21:P21<>"")*(평가!C26:P26<>"")*(평가!C21:P21=평가!C26:P26))/SUMPRODUCT((평가!C21:P21<>"")*(평가!C26:P26<>"")),"") | W20: =IFERROR(SUMPRODUCT((평가!C21:P21<>"")*(평가!C27:P27<>"")*(평가!C21:P21=평가!C27:P27))/SUMPRODUCT((평가!C21:P21<>"")*(평가!C27:P27<>"")),"") | X20: =IFERROR(SUMPRODUCT((평가!C21:P21<>"")*(평가!C28:P28<>"")*(평가!C21:P21=평가!C28:P28))/SUMPRODUCT((평가!C21:P21<>"")*(평가!C28:P28<>"")),"") | Y20: =IFERROR(SUMPRODUCT((평가!C21:P21<>"")*(평가!C29:P29<>"")*(평가!C21:P21=평가!C29:P29))/SUMPRODUCT((평가!C21:P21<>"")*(평가!C29:P29<>"")),"")
A21: 화학공학과 | B21: =IFERROR(SUMPRODUCT((평가!C22:P22<>"")*(평가!C6:P6<>"")*(평가!C22:P22=평가!C6:P6))/SUMPRODUCT((평가!C22:P22<>"")*(평가!C6:P6<>"")),"") | C21: =IFERROR(SUMPRODUCT((평가!C22:P22<>"")*(평가!C7:P7<>"")*(평가!C22:P22=평가!C7:P7))/SUMPRODUCT((평가!C22:P22<>"")*(평가!C7:P7<>"")),"") | D21: =IFERROR(SUMPRODUCT((평가!C22:P22<>"")*(평가!C8:P8<>"")*(평가!C22:P22=평가!C8:P8))/SUMPRODUCT((평가!C22:P22<>"")*(평가!C8:P8<>"")),"") | E21: =IFERROR(SUMPRODUCT((평가!C22:P22<>"")*(평가!C9:P9<>"")*(평가!C22:P22=평가!C9:P9))/SUMPRODUCT((평가!C22:P22<>"")*(평가!C9:P9<>"")),"") | F21: =IFERROR(SUMPRODUCT((평가!C22:P22<>"")*(평가!C10:P10<>"")*(평가!C22:P22=평가!C10:P10))/SUMPRODUCT((평가!C22:P22<>"")*(평가!C10:P10<>"")),"") | G21: =IFERROR(SUMPRODUCT((평가!C22:P22<>"")*(평가!C11:P11<>"")*(평가!C22:P22=평가!C11:P11))/SUMPRODUCT((평가!C22:P22<>"")*(평가!C11:P11<>"")),"") | H21: =IFERROR(SUMPRODUCT((평가!C22:P22<>"")*(평가!C12:P12<>"")*(평가!C22:P22=평가!C12:P12))/SUMPRODUCT((평가!C22:P22<>"")*(평가!C12:P12<>"")),"") | I21: =IFERROR(SUMPRODUCT((평가!C22:P22<>"")*(평가!C13:P13<>"")*(평가!C22:P22=평가!C13:P13))/SUMPRODUCT((평가!C22:P22<>"")*(평가!C13:P13<>"")),"") | J21: =IFERROR(SUMPRODUCT((평가!C22:P22<>"")*(평가!C14:P14<>"")*(평가!C22:P22=평가!C14:P14))/SUMPRODUCT((평가!C22:P22<>"")*(평가!C14:P14<>"")),"") | K21: =IFERROR(SUMPRODUCT((평가!C22:P22<>"")*(평가!C15:P15<>"")*(평가!C22:P22=평가!C15:P15))/SUMPRODUCT((평가!C22:P22<>"")*(평가!C15:P15<>"")),"") | L21: =IFERROR(SUMPRODUCT((평가!C22:P22<>"")*(평가!C16:P16<>"")*(평가!C22:P22=평가!C16:P16))/SUMPRODUCT((평가!C22:P22<>"")*(평가!C16:P16<>"")),"") | M21: =IFERROR(SUMPRODUCT((평가!C22:P22<>"")*(평가!C17:P17<>"")*(평가!C22:P22=평가!C17:P17))/SUMPRODUCT((평가!C22:P22<>"")*(평가!C17:P17<>"")),"") | N21: =IFERROR(SUMPRODUCT((평가!C22:P22<>"")*(평가!C18:P18<>"")*(평가!C22:P22=평가!C18:P18))/SUMPRODUCT((평가!C22:P22<>"")*(평가!C18:P18<>"")),"") | O21: =IFERROR(SUMPRODUCT((평가!C22:P22<>"")*(평가!C19:P19<>"")*(평가!C22:P22=평가!C19:P19))/SUMPRODUCT((평가!C22:P22<>"")*(평가!C19:P19<>"")),"") | P21: =IFERROR(SUMPRODUCT((평가!C22:P22<>"")*(평가!C20:P20<>"")*(평가!C22:P22=평가!C20:P20))/SUMPRODUCT((평가!C22:P22<>"")*(평가!C20:P20<>"")),"") | Q21: =IFERROR(SUMPRODUCT((평가!C22:P22<>"")*(평가!C21:P21<>"")*(평가!C22:P22=평가!C21:P21))/SUMPRODUCT((평가!C22:P22<>"")*(평가!C21:P21<>"")),"") | R21: ="-" | S21: =IFERROR(SUMPRODUCT((평가!C22:P22<>"")*(평가!C23:P23<>"")*(평가!C22:P22=평가!C23:P23))/SUMPRODUCT((평가!C22:P22<>"")*(평가!C23:P23<>"")),"") | T21: =IFERROR(SUMPRODUCT((평가!C22:P22<>"")*(평가!C24:P24<>"")*(평가!C22:P22=평가!C24:P24))/SUMPRODUCT((평가!C22:P22<>"")*(평가!C24:P24<>"")),"") | U21: =IFERROR(SUMPRODUCT((평가!C22:P22<>"")*(평가!C25:P25<>"")*(평가!C22:P22=평가!C25:P25))/SUMPRODUCT((평가!C22:P22<>"")*(평가!C25:P25<>"")),"") | V21: =IFERROR(SUMPRODUCT((평가!C22:P22<>"")*(평가!C26:P26<>"")*(평가!C22:P22=평가!C26:P26))/SUMPRODUCT((평가!C22:P22<>"")*(평가!C26:P26<>"")),"") | W21: =IFERROR(SUMPRODUCT((평가!C22:P22<>"")*(평가!C27:P27<>"")*(평가!C22:P22=평가!C27:P27))/SUMPRODUCT((평가!C22:P22<>"")*(평가!C27:P27<>"")),"") | X21: =IFERROR(SUMPRODUCT((평가!C22:P22<>"")*(평가!C28:P28<>"")*(평가!C22:P22=평가!C28:P28))/SUMPRODUCT((평가!C22:P22<>"")*(평가!C28:P28<>"")),"") | Y21: =IFERROR(SUMPRODUCT((평가!C22:P22<>"")*(평가!C29:P29<>"")*(평가!C22:P22=평가!C29:P29))/SUMPRODUCT((평가!C22:P22<>"")*(평가!C29:P29<>"")),"")
A22: 디자인학과 | B22: =IFERROR(SUMPRODUCT((평가!C23:P23<>"")*(평가!C6:P6<>"")*(평가!C23:P23=평가!C6:P6))/SUMPRODUCT((평가!C23:P23<>"")*(평가!C6:P6<>"")),"") | C22: =IFERROR(SUMPRODUCT((평가!C23:P23<>"")*(평가!C7:P7<>"")*(평가!C23:P23=평가!C7:P7))/SUMPRODUCT((평가!C23:P23<>"")*(평가!C7:P7<>"")),"") | D22: =IFERROR(SUMPRODUCT((평가!C23:P23<>"")*(평가!C8:P8<>"")*(평가!C23:P23=평가!C8:P8))/SUMPRODUCT((평가!C23:P23<>"")*(평가!C8:P8<>"")),"") | E22: =IFERROR(SUMPRODUCT((평가!C23:P23<>"")*(평가!C9:P9<>"")*(평가!C23:P23=평가!C9:P9))/SUMPRODUCT((평가!C23:P23<>"")*(평가!C9:P9<>"")),"") | F22: =IFERROR(SUMPRODUCT((평가!C23:P23<>"")*(평가!C10:P10<>"")*(평가!C23:P23=평가!C10:P10))/SUMPRODUCT((평가!C23:P23<>"")*(평가!C10:P10<>"")),"") | G22: =IFERROR(SUMPRODUCT((평가!C23:P23<>"")*(평가!C11:P11<>"")*(평가!C23:P23=평가!C11:P11))/SUMPRODUCT((평가!C23:P23<>"")*(평가!C11:P11<>"")),"") | H22: =IFERROR(SUMPRODUCT((평가!C23:P23<>"")*(평가!C12:P12<>"")*(평가!C23:P23=평가!C12:P12))/SUMPRODUCT((평가!C23:P23<>"")*(평가!C12:P12<>"")),"") | I22: =IFERROR(SUMPRODUCT((평가!C23:P23<>"")*(평가!C13:P13<>"")*(평가!C23:P23=평가!C13:P13))/SUMPRODUCT((평가!C23:P23<>"")*(평가!C13:P13<>"")),"") | J22: =IFERROR(SUMPRODUCT((평가!C23:P23<>"")*(평가!C14:P14<>"")*(평가!C23:P23=평가!C14:P14))/SUMPRODUCT((평가!C23:P23<>"")*(평가!C14:P14<>"")),"") | K22: =IFERROR(SUMPRODUCT((평가!C23:P23<>"")*(평가!C15:P15<>"")*(평가!C23:P23=평가!C15:P15))/SUMPRODUCT((평가!C23:P23<>"")*(평가!C15:P15<>"")),"") | L22: =IFERROR(SUMPRODUCT((평가!C23:P23<>"")*(평가!C16:P16<>"")*(평가!C23:P23=평가!C16:P16))/SUMPRODUCT((평가!C23:P23<>"")*(평가!C16:P16<>"")),"") | M22: =IFERROR(SUMPRODUCT((평가!C23:P23<>"")*(평가!C17:P17<>"")*(평가!C23:P23=평가!C17:P17))/SUMPRODUCT((평가!C23:P23<>"")*(평가!C17:P17<>"")),"") | N22: =IFERROR(SUMPRODUCT((평가!C23:P23<>"")*(평가!C18:P18<>"")*(평가!C23:P23=평가!C18:P18))/SUMPRODUCT((평가!C23:P23<>"")*(평가!C18:P18<>"")),"") | O22: =IFERROR(SUMPRODUCT((평가!C23:P23<>"")*(평가!C19:P19<>"")*(평가!C23:P23=평가!C19:P19))/SUMPRODUCT((평가!C23:P23<>"")*(평가!C19:P19<>"")),"") | P22: =IFERROR(SUMPRODUCT((평가!C23:P23<>"")*(평가!C20:P20<>"")*(평가!C23:P23=평가!C20:P20))/SUMPRODUCT((평가!C23:P23<>"")*(평가!C20:P20<>"")),"") | Q22: =IFERROR(SUMPRODUCT((평가!C23:P23<>"")*(평가!C21:P21<>"")*(평가!C23:P23=평가!C21:P21))/SUMPRODUCT((평가!C23:P23<>"")*(평가!C21:P21<>"")),"") | R22: =IFERROR(SUMPRODUCT((평가!C23:P23<>"")*(평가!C22:P22<>"")*(평가!C23:P23=평가!C22:P22))/SUMPRODUCT((평가!C23:P23<>"")*(평가!C22:P22<>"")),"") | S22: ="-" | T22: =IFERROR(SUMPRODUCT((평가!C23:P23<>"")*(평가!C24:P24<>"")*(평가!C23:P23=평가!C24:P24))/SUMPRODUCT((평가!C23:P23<>"")*(평가!C24:P24<>"")),"") | U22: =IFERROR(SUMPRODUCT((평가!C23:P23<>"")*(평가!C25:P25<>"")*(평가!C23:P23=평가!C25:P25))/SUMPRODUCT((평가!C23:P23<>"")*(평가!C25:P25<>"")),"") | V22: =IFERROR(SUMPRODUCT((평가!C23:P23<>"")*(평가!C26:P26<>"")*(평가!C23:P23=평가!C26:P26))/SUMPRODUCT((평가!C23:P23<>"")*(평가!C26:P26<>"")),"") | W22: =IFERROR(SUMPRODUCT((평가!C23:P23<>"")*(평가!C27:P27<>"")*(평가!C23:P23=평가!C27:P27))/SUMPRODUCT((평가!C23:P23<>"")*(평가!C27:P27<>"")),"") | X22: =IFERROR(SUMPRODUCT((평가!C23:P23<>"")*(평가!C28:P28<>"")*(평가!C23:P23=평가!C28:P28))/SUMPRODUCT((평가!C23:P23<>"")*(평가!C28:P28<>"")),"") | Y22: =IFERROR(SUMPRODUCT((평가!C23:P23<>"")*(평가!C29:P29<>"")*(평가!C23:P23=평가!C29:P29))/SUMPRODUCT((평가!C23:P23<>"")*(평가!C29:P29<>"")),"")
